Workbook

Sheet 2027 会议主表
A1: 序号 | B1: 简称 | C1: 全称 | D1: 研究主题 | E1: 方向 | F1: CCF | G1: 摘要截稿 (北京) | H1: 正文截稿 (北京) | I1: 轮次 | J1: 原始时区 | K1: Rebuttal (北京) | L1: 录用通知 (北京) | M1: 状态 | N1: 剩余 天数 | O1: 会期 | P1: 地点 | Q1: 举办形式 | R1: 是否必须到场 | S1: 远程参会 | T1: 投稿上限 (篇) | U1: 上限口径 | V1: 新人作者条款 | W1: 官网核查 | X1: 信息缺口 | Y1: 官网 | Z1: 备注
A2: 1 | B2: AAAI | C2: AAAI Conference on Artificial Intelligence | D2: AI 综合顶会，符号推理与规划传统强，也收 ML 各方向应用 | E2: 人工智能 | F2: A | G2: 46225.833 | H2: 46232.833 | I2: 单轮 | J2: UTC-12 | K2: 46321.833 | L2: 2026-11-30 | M2: =IF(ISNUMBER(H2),IF(H2>'_轮次'!$A$1,"未截止","已截止"),"TBD") | N2: =IF(ISNUMBER(H2),IF(H2>'_轮次'!$A$1,INT(H2-'_轮次'!$A$1),"—"),"—") | O2: February 16-23, 2027 | P2: Montréal, Québec, Canada | Q2: 线下 | R2: 必须到场 | S2: 提供付费 virtual 参会 | T2: 不限 | U2: — | V2: 未找到 | W2: 已核实 | X2: 新人条款 | Y2: https://aaai.org/conference/aaai/aaai-27/ | Z2: 近年投稿量极大，录取率约 20% 上下；核查:摘要07-21，全文07-28；日程页未写宣讲与远程政策
A3: 2 | B3: ACL | C3: Annual Meeting of the Association for Computational Linguistics | D3: 自然语言处理第一大会，句法语义到 LLM 应用全覆盖，重视评测 | E3: 人工智能 | F3: A | G3: — | H3: 46392.833 | I3: ARR Submission | J3: UTC-12 | K3: — | L3: 待公布 | M3: =IF(ISNUMBER(H3),IF(H3>'_轮次'!$A$1,"未截止","已截止"),"TBD") | N3: =IF(ISNUMBER(H3),IF(H3>'_轮次'!$A$1,INT(H3-'_轮次'!$A$1),"—"),"—") | O3: August 17-22, 2027 | P3: Kyoto, Japan | Q3: 线下 | R3: 允许远程 | S3: in-person 与 virtual 两种宣讲均可 | T3: 不限 | U3: — | V3: 未找到 | W3: 已核实 | X3: 新人条款 | Y3: https://2027.aclweb.org/ | Z3: 经 ACL Rolling Review 提交，再承诺至会议；核查:须至少一位作者注册并宣讲；录用通知日TBD
A4: 3 | B4: CVPR | C4: IEEE/CVF Conference on Computer Vision and Pattern Recognition | D4: 计算机视觉第一大会，识别/检测/生成/三维全覆盖，看重实验规模 | E4: 人工智能 | F4: A | G4: 46337.833 | H4: 46343.833 | I4: 单轮 | J4: UTC-12 | K4: 46420.833 | L4: 2027-02-25 | M4: =IF(ISNUMBER(H4),IF(H4>'_轮次'!$A$1,"未截止","已截止"),"TBD") | N4: =IF(ISNUMBER(H4),IF(H4>'_轮次'!$A$1,INT(H4-'_轮次'!$A$1),"—"),"—") | O4: June 20-25, 2027 | P4: Seattle, WA, United States | Q4: 线下 | R4: 必须到场 | S4: 不设线上报告通道 | T4: 不限 | U4: — | V4: 硬性｜全体作者须应召担任审稿人，豁免须事前申请 | W4: 已核实 | X4: — | Y4: https://cvpr.thecvf.com/Conferences/2027 | Z4: 每年 11 月截稿，6 月开会；核查:论文注册11-10；CFP未明写现场宣讲要求
A5: 4 | B5: ICCV | C5: IEEE International Conference on Computer Vision | D5: 计算机视觉三大顶会之一，偏重算法创新与理论分析，两年一届 | E5: 人工智能 | F5: A | G5: — | H5: 待公布 | I5: — | J5: AoE | K5: — | L5: 待公布 | M5: =IF(ISNUMBER(H5),IF(H5>'_轮次'!$A$1,"未截止","已截止"),"TBD") | N5: =IF(ISNUMBER(H5),IF(H5>'_轮次'!$A$1,INT(H5-'_轮次'!$A$1),"—"),"—") | O5: October 2-8, 2027 | P5: Hong Kong, China | Q5: 线下 | R5: 必须到场 | S5: 不设线上报告通道 | T5: 不限 | U5: — | V5: CFP未发布 | W5: 2027CFP未发布 | X5: 截稿日、新人条款 | Y5: https://iccv.thecvf.com/Conferences/2027 | Z5: 奇数年举办，2027 届正常召开；核查:官网仅公布时间地点(10/3-7)，CFP未出
A6: 5 | B6: ICLR | C6: International Conference on Learning Representations | D6: 表征学习与深度学习前沿阵地，LLM 时代影响力最大，开放评审 | E6: 人工智能 | F6: A | G6: 46284.833 | H6: 46291.833 | I6: 单轮 | J6: AoE | K6: 46345.833 | L6: 2026-12-16 | M6: =IF(ISNUMBER(H6),IF(H6>'_轮次'!$A$1,"未截止","已截止"),"TBD") | N6: =IF(ISNUMBER(H6),IF(H6>'_轮次'!$A$1,INT(H6-'_轮次'!$A$1),"—"),"—") | O6: April 26-30, 2027 | P6: San Francisco, CA, USA | Q6: 混合 | R6: 允许远程 | S6: 免费线上参会并可远程报告 | T6: 20 | U6: 每届 | V6: 硬性｜须指定作者注册审稿≥3 篇，否则直接拒稿 | W6: 已核实 | X6: — | Y6: https://iclr.cc/Conferences/2027 | Z6: 评审意见与讨论全程公开；核查:署名≥3篇须审6篇；出席形式未明示
A7: 6 | B7: ACM SIGGRAPH | C7: ACM SIGGRAPH Annual Conference | D7: 图形学与交互技术第一大会，渲染/几何/动画，重系统与艺术表达 | E7: 图形学与多媒体 | F7: A | G7: — | H7: 待公布 | I7: — | J7: UTC+0 | K7: — | L7: 待公布 | M7: =IF(ISNUMBER(H7),IF(H7>'_轮次'!$A$1,"未截止","已截止"),"TBD") | N7: =IF(ISNUMBER(H7),IF(H7>'_轮次'!$A$1,INT(H7-'_轮次'!$A$1),"—"),"—") | O7: August 8 - 12, 2027 | P7: Anaheim, California | Q7: 线下 | R7: 必须到场 | S7: 提供付费线上参会 | T7: 不限 | U7: — | V7: CFP未发布 | W7: 2027CFP未发布 | X7: 截稿日、新人条款 | Y7: https://s2027.siggraph.org/ | Z7: 分技术论文与 Art Papers 等多轨道；核查:第三方站点称Stage1为2027-01-21，官网未见
A8: 7 | B8: IEEE VR | C8: IEEE Virtual Reality | D8: 虚拟现实与增强现实顶会，追踪/显示/交互/感知，偏系统与用户研究 | E8: 图形学与多媒体 | F8: A | G8: 46259.833 | H8: 46266.833 | I8: 单轮 | J8: AoE | K8: — | L8: 2027-01-07 | M8: =IF(ISNUMBER(H8),IF(H8>'_轮次'!$A$1,"未截止","已截止"),"TBD") | N8: =IF(ISNUMBER(H8),IF(H8>'_轮次'!$A$1,INT(H8-'_轮次'!$A$1),"—"),"—") | O8: February 27 - March 3, 2027 | P8: Melbourne, Australia | Q8: 线下 | R8: 必须到场 | S8: 仅特殊情况允许线上宣讲 | T8: 不限 | U8: — | V8: 硬性｜资深作者须注册审稿，评审数≥投稿数，失责可拒稿 | W8: 已核实 | X8: — | Y8: https://ieeevr.org/2027/ | Z8: 期刊轨与会议轨并行，TVCG 出版；核查:截稿已过(2026-08-31)；资深作者须任审稿人
A9: 8 | B9: CAV | C9: International Conference on Computer-Aided Verification | D9: 计算机辅助验证顶会，模型检验/程序验证/SMT，形式化方法核心 | E9: 计算机科学理论 | F9: A | G9: — | H9: 46408.833 | I9: 单轮 | J9: AoE | K9: 46486.833 | L9: 2027-04-23 | M9: =IF(ISNUMBER(H9),IF(H9>'_轮次'!$A$1,"未截止","已截止"),"TBD") | N9: =IF(ISNUMBER(H9),IF(H9>'_轮次'!$A$1,INT(H9-'_轮次'!$A$1),"—"),"—") | O9: July 19-23, 2027 | P9: KIT, Amsterdam, The Netherlands | Q9: 线下 | R9: 待确认 | S9: 待确认 | T9: 5 | U9: 每届 | V9: 无专属条款 | W9: 已核实 | X9: 是否到场 | Y9: https://conferences.i-cav.org/2027/ | Z9: LNCS 出版，另设 artifact 评审；核查:全文2027-01-20；每作者限投5篇（含三类）
A10: 9 | B10: LICS | C10: IEEE Symposium on Logic in Computer Science | D10: 逻辑与计算机科学交叉顶会，证明论/语义/类型论，理论性强 | E10: 计算机科学理论 | F10: A | G10: — | H10: 待公布 | I10: — | J10: AoE | K10: — | L10: 待公布 | M10: =IF(ISNUMBER(H10),IF(H10>'_轮次'!$A$1,"未截止","已截止"),"TBD") | N10: =IF(ISNUMBER(H10),IF(H10>'_轮次'!$A$1,INT(H10-'_轮次'!$A$1),"—"),"—") | O10: June 21-24, 2027 | P10: Montréal, Canada | Q10: 线下 | R10: 待确认 | S10: 待确认 | T10: 不限 | U10: — | V10: CFP未发布 | W10: 2027CFP未发布 | X10: 截稿日、是否到场、新人条款 | Y10: https://lics.siglog.org/lics27/ | Z10: 常与 ICALP 等逻辑类会议联办；核查:官网仅占位页，注明信息稍后公布
A11: 10 | B11: SODA | C11: ACM-SIAM Symposium on Discrete Algorithms | D11: 离散算法理论顶会，算法设计与下界证明，与 STOC/FOCS 互补 | E11: 计算机科学理论 | F11: A | G11: — | H11: 46213.833 | I11: 单轮 | J11: UTC-12 | K11: 46270.833 | L11: 待公布 | M11: =IF(ISNUMBER(H11),IF(H11>'_轮次'!$A$1,"未截止","已截止"),"TBD") | N11: =IF(ISNUMBER(H11),IF(H11>'_轮次'!$A$1,INT(H11-'_轮次'!$A$1),"—"),"—") | O11: January 24-27, 2027 | P11: Philadelphia, Pennsylvania, USA | Q11: 线下 | R11: 必须到场 | S11: 不接受远程或录播报告 | T11: 不限 | U11: — | V11: 利好｜通道 最佳学生论文奖（全学生作者可评） | W11: 已核实 | X11: — | Y11: https://www.siam.org/conferences-events/siam-conferences/soda27/ | Z11: 与 ALENEX/ANALCO 同期同地举办；核查:录用通知仅写2026年10月，无具体日
A12: 11 | B12: STOC | C12: ACM Symposium on the Theory of Computing | D12: 理论计算机科学最高级别会议，复杂度/算法/密码基础理论 | E12: 计算机科学理论 | F12: A | G12: — | H12: 46329.833 | I12: 单轮 | J12: UTC-12 | K12: — | L12: 2027-02-01 | M12: =IF(ISNUMBER(H12),IF(H12>'_轮次'!$A$1,"未截止","已截止"),"TBD") | N12: =IF(ISNUMBER(H12),IF(H12>'_轮次'!$A$1,INT(H12-'_轮次'!$A$1),"—"),"—") | O12: June 6-11, 2027 | P12: Atlanta, Georgia, USA | Q12: 线下 | R12: 必须到场 | S12: 无正式远程，需提前联系主席 | T12: 5 | U12: 每届 | V12: 硬性｜配额 5 篇（每位作者各自计，适用于所有作者） | W12: 已核实 | X12: — | Y12: https://acm-stoc.org/stoc2027/ | Z12: 与 FOCS 并列为理论两大顶会；核查:强制公开发布投稿并提交20-30分钟视频
A13: 12 | B13: ICDE | C13: IEEE International Conference on Data Engineering | D13: 数据工程三大顶会之一，数据库系统/查询优化/数据管理全方向 | E13: 数据库/数据挖掘 | F13: A | G13: =IF(ISNUMBER(H13),IF(N(INDEX('_轮次'!$N$13:$Y$13,MATCH(H13,'_轮次'!$B$13:$M$13,0)))=0,"—",INDEX('_轮次'!$N$13:$Y$13,MATCH(H13,'_轮次'!$B$13:$M$13,0))),"—") | H13: =IF(COUNT('_轮次'!$B$13:$M$13)=0,"待公布",IF(COUNTIF('_轮次'!$B$13:$M$13,">"&'_轮次'!$A$1)>0,SMALL('_轮次'!$B$13:$M$13,COUNTIF('_轮次'!$B$13:$M$13,"<="&'_轮次'!$A$1)+1),MAX('_轮次'!$B$13:$M$13))) | I13: =IF(ISNUMBER(H13),INDEX('_轮次'!$AX$13:$BI$13,MATCH(H13,'_轮次'!$B$13:$M$13,0)),"—") | J13: PT | K13: =IF(ISNUMBER(H13),IF(N(INDEX('_轮次'!$Z$13:$AK$13,MATCH(H13,'_轮次'!$B$13:$M$13,0)))=0,"—",INDEX('_轮次'!$Z$13:$AK$13,MATCH(H13,'_轮次'!$B$13:$M$13,0))),"—") | L13: =IF(ISNUMBER(H13),IF(N(INDEX('_轮次'!$AL$13:$AW$13,MATCH(H13,'_轮次'!$B$13:$M$13,0)))=0,"—",INDEX('_轮次'!$AL$13:$AW$13,MATCH(H13,'_轮次'!$B$13:$M$13,0))),"—") | M13: =IF(ISNUMBER(H13),IF(H13>'_轮次'!$A$1,"未截止","已截止"),"TBD") | N13: =IF(ISNUMBER(H13),IF(H13>'_轮次'!$A$1,INT(H13-'_轮次'!$A$1),"—"),"—") | O13: May 17-21, 2027 | P13: Copenhagen, Denmark | Q13: 线下 | R13: 必须到场 | S13: 待确认 | T13: 不限 | U13: — | V13: 硬性｜配额 5 篇（每轮，研究轨道） | W13: 已核实 | X13: — | Y13: https://icde2027.github.io/ | Z13: IEEE 主办，分研究轨与工业轨；核查:研究主会两轮，第一轮2026-06-11已截；全部轮次 first round:2026-06-12 / second round:2026-11-12
A14: 13 | B14: SIGIR | C14: International Conference on Research on Development in Information Retrieval | D14: 信息检索第一大会，检索模型/排序/推荐/对话式检索，评测导向 | E14: 数据库/数据挖掘 | F14: A | G14: 46402.833 | H14: 46409.833 | I14: 单轮 | J14: AoE | K14: — | L14: 2027-04-05 | M14: =IF(ISNUMBER(H14),IF(H14>'_轮次'!$A$1,"未截止","已截止"),"TBD") | N14: =IF(ISNUMBER(H14),IF(H14>'_轮次'!$A$1,INT(H14-'_轮次'!$A$1),"—"),"—") | O14: July 18-24, 2027 | P14: San Jose, California, USA | Q14: 线下 | R14: 必须到场 | S14: 待确认 | T14: 不限 | U14: — | V14: 利好｜通道 Doctoral Consortium | W14: 已核实 | X14: — | Y14: https://sigir2027.org/ | Z14: 设 Resource、Demo、Industry 等子轨道；核查:摘要2027-01-14；短论文等日期标TBA
A15: 14 | B15: SIGKDD | C15: ACM Knowledge Discovery and Data Mining | D15: 数据挖掘第一大会，图学习/推荐/时序/大模型数据应用，工业界重 | E15: 数据库/数据挖掘 | F15: A | G15: 46223.833 | H15: 46230.833 | I15: 1st round of 2 total rounds | J15: AoE | K15: 46309.833 | L15: 2026-11-14 | M15: =IF(ISNUMBER(H15),IF(H15>'_轮次'!$A$1,"未截止","已截止"),"TBD") | N15: =IF(ISNUMBER(H15),IF(H15>'_轮次'!$A$1,INT(H15-'_轮次'!$A$1),"—"),"—") | O15: August 1-5, 2027 | P15: San Jose, California, USA | Q15: 线下 | R15: 必须到场 | S15: 待确认 | T15: 7 | U15: 每届 | V15: 硬性｜须提名 1 名合格审稿人（KDD 等≥3 篇） | W15: 已核实 | X15: — | Y15: https://kdd2027.kdd.org/ | Z15: 研究轨与 Applied Data Science 轨分开投；核查:第一轮；每轮每作者最多7篇，第二轮日期未公布
A16: 15 | B16: SIGMOD | C16: ACM Conference on Management of Data | D16: 数据库第一大会，数据系统/存储引擎/事务与查询处理，系统实现重 | E16: 数据库/数据挖掘 | F16: A | G16: =IF(ISNUMBER(H16),IF(N(INDEX('_轮次'!$N$16:$Y$16,MATCH(H16,'_轮次'!$B$16:$M$16,0)))=0,"—",INDEX('_轮次'!$N$16:$Y$16,MATCH(H16,'_轮次'!$B$16:$M$16,0))),"—") | H16: =IF(COUNT('_轮次'!$B$16:$M$16)=0,"待公布",IF(COUNTIF('_轮次'!$B$16:$M$16,">"&'_轮次'!$A$1)>0,SMALL('_轮次'!$B$16:$M$16,COUNTIF('_轮次'!$B$16:$M$16,"<="&'_轮次'!$A$1)+1),MAX('_轮次'!$B$16:$M$16))) | I16: =IF(ISNUMBER(H16),INDEX('_轮次'!$AX$16:$BI$16,MATCH(H16,'_轮次'!$B$16:$M$16,0)),"—") | J16: AoE | K16: =IF(ISNUMBER(H16),IF(N(INDEX('_轮次'!$Z$16:$AK$16,MATCH(H16,'_轮次'!$B$16:$M$16,0)))=0,"—",INDEX('_轮次'!$Z$16:$AK$16,MATCH(H16,'_轮次'!$B$16:$M$16,0))),"—") | L16: =IF(ISNUMBER(H16),IF(N(INDEX('_轮次'!$AL$16:$AW$16,MATCH(H16,'_轮次'!$B$16:$M$16,0)))=0,"—",INDEX('_轮次'!$AL$16:$AW$16,MATCH(H16,'_轮次'!$B$16:$M$16,0))),"—") | M16: =IF(ISNUMBER(H16),IF(H16>'_轮次'!$A$1,"未截止","已截止"),"TBD") | N16: =IF(ISNUMBER(H16),IF(H16>'_轮次'!$A$1,INT(H16-'_轮次'!$A$1),"—"),"—") | O16: June 13-19, 2027 | P16: Huntington Beach, CA, USA | Q16: 线下 | R16: 必须到场 | S16: 待确认 | T16: 10 | U16: 每届 | V16: 未找到 | W16: 已核实 | X16: 新人条款 | Y16: https://2027.sigmod.org/ | Z16: 一年两轮投稿，PACMMOD 出版；核查:四轮截稿，取末轮R4；终审通知2027-03-12；全部轮次 round 1:2026-01-18 / round 2:2026-04-18 / round 3:2026-07-18 / round 4:2026-10-18
A17: 16 | B17: VLDB | C17: International Conference on Very Large Data Bases | D17: 数据库与数据管理顶会，系统/存储/查询/新型硬件，工业论文占比高 | E17: 数据库/数据挖掘 | F17: A | G17: =IF(ISNUMBER(H17),IF(N(INDEX('_轮次'!$N$17:$Y$17,MATCH(H17,'_轮次'!$B$17:$M$17,0)))=0,"—",INDEX('_轮次'!$N$17:$Y$17,MATCH(H17,'_轮次'!$B$17:$M$17,0))),"—") | H17: =IF(COUNT('_轮次'!$B$17:$M$17)=0,"待公布",IF(COUNTIF('_轮次'!$B$17:$M$17,">"&'_轮次'!$A$1)>0,SMALL('_轮次'!$B$17:$M$17,COUNTIF('_轮次'!$B$17:$M$17,"<="&'_轮次'!$A$1)+1),MAX('_轮次'!$B$17:$M$17))) | I17: =IF(ISNUMBER(H17),INDEX('_轮次'!$AX$17:$BI$17,MATCH(H17,'_轮次'!$B$17:$M$17,0)),"—") | J17: PT | K17: =IF(ISNUMBER(H17),IF(N(INDEX('_轮次'!$Z$17:$AK$17,MATCH(H17,'_轮次'!$B$17:$M$17,0)))=0,"—",INDEX('_轮次'!$Z$17:$AK$17,MATCH(H17,'_轮次'!$B$17:$M$17,0))),"—") | L17: =IF(ISNUMBER(H17),IF(N(INDEX('_轮次'!$AL$17:$AW$17,MATCH(H17,'_轮次'!$B$17:$M$17,0)))=0,"—",INDEX('_轮次'!$AL$17:$AW$17,MATCH(H17,'_轮次'!$B$17:$M$17,0))),"—") | M17: =IF(ISNUMBER(H17),IF(H17>'_轮次'!$A$1,"未截止","已截止"),"TBD") | N17: =IF(ISNUMBER(H17),IF(H17>'_轮次'!$A$1,INT(H17-'_轮次'!$A$1),"—"),"—") | O17: August 23 - August 27, 2027 | P17: Athens, Greece | Q17: 线下 | R17: 必须到场 | S17: 待确认 | T17: 12 | U17: 每年（每月≤2） | V17: 硬性｜须提名 1 名合格审稿人（VLDB 等≥2 篇） | W17: 已核实 | X17: — | Y17: https://www.vldb.org/2027/ | Z17: 按月滚动投稿，PVLDB 出版；核查:每月1日滚动截稿，此处取最终截稿日；全部轮次 轮:2026-04-02 / 轮:2026-05-02 / 轮:2026-06-02 / 轮:2026-07-02 / 轮:2026-08-02 / 轮:2026-09-02 / 轮:2026-10-02 / 轮:2026-11-02 / 轮:2026-12-02 / 轮:2027-01-02 / 轮:2027-02-02 / 轮:2027-03-02
A18: 17 | B18: ASPLOS | C18: International Conference on Architectural Support for Programming Languages and Operating Systems | D18: 系统结构顶会，体系结构/编译/操作系统交叉，硬件软件协同设计 | E18: 体系结构/并行/存储 | F18: A | G18: =IF(ISNUMBER(H18),IF(N(INDEX('_轮次'!$N$18:$Y$18,MATCH(H18,'_轮次'!$B$18:$M$18,0)))=0,"—",INDEX('_轮次'!$N$18:$Y$18,MATCH(H18,'_轮次'!$B$18:$M$18,0))),"—") | H18: =IF(COUNT('_轮次'!$B$18:$M$18)=0,"待公布",IF(COUNTIF('_轮次'!$B$18:$M$18,">"&'_轮次'!$A$1)>0,SMALL('_轮次'!$B$18:$M$18,COUNTIF('_轮次'!$B$18:$M$18,"<="&'_轮次'!$A$1)+1),MAX('_轮次'!$B$18:$M$18))) | I18: =IF(ISNUMBER(H18),INDEX('_轮次'!$AX$18:$BI$18,MATCH(H18,'_轮次'!$B$18:$M$18,0)),"—") | J18: AoE | K18: =IF(ISNUMBER(H18),IF(N(INDEX('_轮次'!$Z$18:$AK$18,MATCH(H18,'_轮次'!$B$18:$M$18,0)))=0,"—",INDEX('_轮次'!$Z$18:$AK$18,MATCH(H18,'_轮次'!$B$18:$M$18,0))),"—") | L18: =IF(ISNUMBER(H18),IF(N(INDEX('_轮次'!$AL$18:$AW$18,MATCH(H18,'_轮次'!$B$18:$M$18,0)))=0,"—",INDEX('_轮次'!$AL$18:$AW$18,MATCH(H18,'_轮次'!$B$18:$M$18,0))),"—") | M18: =IF(ISNUMBER(H18),IF(H18>'_轮次'!$A$1,"未截止","已截止"),"TBD") | N18: =IF(ISNUMBER(H18),IF(H18>'_轮次'!$A$1,INT(H18-'_轮次'!$A$1),"—"),"—") | O18: April 11-15, 2027 | P18: Crete, Greece | Q18: 线下 | R18: 必须到场 | S18: 待确认 | T18: 4 | U18: 每届 | V18: 无专属条款 | W18: 已核实 | X18: — | Y18: https://www.asplos-conference.org/asplos2027/cfp/ | Z18: 一年两轮截稿，ACM 出版；核查:两轮截稿(4/15、9/9)，此处取九月周期；全部轮次 April Cycle Submission Deadline:2026-04-16 / September Cycle Submission Deadline:2026-09-10
A19: 18 | B19: DAC | C19: Design Automation Conference | D19: EDA 领域第一会，芯片设计/验证/物理设计为主，兼收 AI 加速器与硬件安全 | E19: 体系结构/并行/存储 | F19: A | G19: 46338.375 | H19: 46345.375 | I19: 单轮 | J19: UTC-8 | K19: — | L19: 2027-03-08 | M19: =IF(ISNUMBER(H19),IF(H19>'_轮次'!$A$1,"未截止","已截止"),"TBD") | N19: =IF(ISNUMBER(H19),IF(H19>'_轮次'!$A$1,INT(H19-'_轮次'!$A$1),"—"),"—") | O19: July 11-14, 2027 | P19: San Jose, CA | Q19: 线下 | R19: 必须到场 | S19: 待确认 | T19: 不限 | U19: — | V19: 无专属条款 | W19: 已核实 | X19: — | Y19: https://dac.com/2027/authors/call-for-contributions | Z19: 工业界参与度高，有设计竞赛与展览；核查:摘要2026-11-11；须注册并现场海报报告
A20: 19 | B20: EuroSys | C20: European Conference on Computer Systems | D20: 欧洲系统顶会，操作系统/分布式/云与虚拟化，重工程实现与真实测量 | E20: 体系结构/并行/存储 | F20: A | G20: =IF(ISNUMBER(H20),IF(N(INDEX('_轮次'!$N$20:$Y$20,MATCH(H20,'_轮次'!$B$20:$M$20,0)))=0,"—",INDEX('_轮次'!$N$20:$Y$20,MATCH(H20,'_轮次'!$B$20:$M$20,0))),"—") | H20: =IF(COUNT('_轮次'!$B$20:$M$20)=0,"待公布",IF(COUNTIF('_轮次'!$B$20:$M$20,">"&'_轮次'!$A$1)>0,SMALL('_轮次'!$B$20:$M$20,COUNTIF('_轮次'!$B$20:$M$20,"<="&'_轮次'!$A$1)+1),MAX('_轮次'!$B$20:$M$20))) | I20: =IF(ISNUMBER(H20),INDEX('_轮次'!$AX$20:$BI$20,MATCH(H20,'_轮次'!$B$20:$M$20,0)),"—") | J20: AoE | K20: =IF(ISNUMBER(H20),IF(N(INDEX('_轮次'!$Z$20:$AK$20,MATCH(H20,'_轮次'!$B$20:$M$20,0)))=0,"—",INDEX('_轮次'!$Z$20:$AK$20,MATCH(H20,'_轮次'!$B$20:$M$20,0))),"—") | L20: =IF(ISNUMBER(H20),IF(N(INDEX('_轮次'!$AL$20:$AW$20,MATCH(H20,'_轮次'!$B$20:$M$20,0)))=0,"—",INDEX('_轮次'!$AL$20:$AW$20,MATCH(H20,'_轮次'!$B$20:$M$20,0))),"—") | M20: =IF(ISNUMBER(H20),IF(H20>'_轮次'!$A$1,"未截止","已截止"),"TBD") | N20: =IF(ISNUMBER(H20),IF(H20>'_轮次'!$A$1,INT(H20-'_轮次'!$A$1),"—"),"—") | O20: April 19-23, 2027 | P20: Rabat, Morocco | Q20: 线下 | R20: 必须到场 | S20: 待确认 | T20: 3 | U20: 每届 | V20: 无专属条款 | W20: 已核实 | X20: — | Y20: https://2027.eurosys.org/ | Z20: 看重可复现性，鼓励 artifact 提交；核查:春秋两轮，取秋季轮；每篇需一份全费注册；全部轮次 Spring Submission Deadline:2026-05-15 / Fall Submission Deadline:2026-09-25
A21: 20 | B21: FAST | C21: USENIX Conference on File and Storage Technologies | D21: 存储领域第一会，文件系统/闪存/分布式存储，重实测与可复现性 | E21: 体系结构/并行/存储 | F21: A | G21: =IF(ISNUMBER(H21),IF(N(INDEX('_轮次'!$N$21:$Y$21,MATCH(H21,'_轮次'!$B$21:$M$21,0)))=0,"—",INDEX('_轮次'!$N$21:$Y$21,MATCH(H21,'_轮次'!$B$21:$M$21,0))),"—") | H21: =IF(COUNT('_轮次'!$B$21:$M$21)=0,"待公布",IF(COUNTIF('_轮次'!$B$21:$M$21,">"&'_轮次'!$A$1)>0,SMALL('_轮次'!$B$21:$M$21,COUNTIF('_轮次'!$B$21:$M$21,"<="&'_轮次'!$A$1)+1),MAX('_轮次'!$B$21:$M$21))) | I21: =IF(ISNUMBER(H21),INDEX('_轮次'!$AX$21:$BI$21,MATCH(H21,'_轮次'!$B$21:$M$21,0)),"—") | J21: AoE | K21: =IF(ISNUMBER(H21),IF(N(INDEX('_轮次'!$Z$21:$AK$21,MATCH(H21,'_轮次'!$B$21:$M$21,0)))=0,"—",INDEX('_轮次'!$Z$21:$AK$21,MATCH(H21,'_轮次'!$B$21:$M$21,0))),"—") | L21: =IF(ISNUMBER(H21),IF(N(INDEX('_轮次'!$AL$21:$AW$21,MATCH(H21,'_轮次'!$B$21:$M$21,0)))=0,"—",INDEX('_轮次'!$AL$21:$AW$21,MATCH(H21,'_轮次'!$B$21:$M$21,0))),"—") | M21: =IF(ISNUMBER(H21),IF(H21>'_轮次'!$A$1,"未截止","已截止"),"TBD") | N21: =IF(ISNUMBER(H21),IF(H21>'_轮次'!$A$1,INT(H21-'_轮次'!$A$1),"—"),"—") | O21: FEBRUARY 23-25, 2027 | P21: Renton, WA, USA | Q21: 线下 | R21: 必须到场 | S21: 无线上报告选项 | T21: 不限 | U21: — | V21: 利好｜通道 WIP/Posters、Mentoring（均设联合主席） | W21: 已核实 | X21: — | Y21: https://www.usenix.org/conference/fast27 | Z21: USENIX 体系，录用后需提交 artifact；核查:春秋两轮，取秋季轮；无独立摘要截稿；全部轮次 Spring deadline:2026-03-18 / Fall deadline:2026-09-16
A22: 21 | B22: HPCA | C22: IEEE International Symposium on High-Performance Computer Architecture | D22: 体系结构三大顶会之一，处理器/缓存/加速器微架构，重创新与仿真评估 | E22: 体系结构/并行/存储 | F22: A | G22: 46228.833 | H22: 46235.833 | I22: 单轮 | J22: AoE | K22: 46307.833 | L22: 2026-11-06 | M22: =IF(ISNUMBER(H22),IF(H22>'_轮次'!$A$1,"未截止","已截止"),"TBD") | N22: =IF(ISNUMBER(H22),IF(H22>'_轮次'!$A$1,INT(H22-'_轮次'!$A$1),"—"),"—") | O22: March 20-24, 2027 | P22: Salt Lake City, Utah | Q22: 线下 | R22: 必须到场 | S22: 待确认 | T22: 不限 | U22: — | V22: 硬性｜每篇须指定资深作者，或须任Light PC审稿≤6篇 | W22: 已核实 | X22: — | Y22: https://conf.researchr.org/home/hpca-2027 | Z22: 与 ISCA、MICRO 合称体系结构三大会；核查:官网track页404，读SIGARCH官方CFP
A23: 22 | B23: ISCA | C23: International Symposium on Computer Architecture | D23: 最老牌体系结构顶会，CPU/内存/加速器架构，重开创性想法与量化评估 | E23: 体系结构/并行/存储 | F23: A | G23: 46336.833 | H23: 46343.833 | I23: Main Track; rebuttal/revision period: February 16-March 8, 2027 | J23: AoE | K23: 46455.833 | L23: 2027-03-26 | M23: =IF(ISNUMBER(H23),IF(H23>'_轮次'!$A$1,"未截止","已截止"),"TBD") | N23: =IF(ISNUMBER(H23),IF(H23>'_轮次'!$A$1,INT(H23-'_轮次'!$A$1),"—"),"—") | O23: June 5-9, 2027 | P23: Atlanta, Georgia, USA | Q23: 线下 | R23: 必须到场 | S23: 待确认 | T23: 8 | U23: 每届 | V23: 硬性｜须指定资深作者任reserve reviewer；投超6篇须任PC | W23: 已核实 | X23: — | Y23: https://iscaconf.org/isca2027/ | Z23: 有 rebuttal 与作者答复环节；核查:摘要2026-11-09截止；CFP未写现场报告要求
A24: 23 | B24: PPoPP | C24: ACM SIGPLAN Symposium on Principles & Practice of Parallel Programming | D24: 并行编程顶会，并行算法/运行时/编译优化与性能可移植性 | E24: 体系结构/并行/存储 | F24: A | G24: — | H24: 46238.833 | I24: 单轮 | J24: AoE | K24: — | L24: 2026-10-26 | M24: =IF(ISNUMBER(H24),IF(H24>'_轮次'!$A$1,"未截止","已截止"),"TBD") | N24: =IF(ISNUMBER(H24),IF(H24>'_轮次'!$A$1,INT(H24-'_轮次'!$A$1),"—"),"—") | O24: Mar 20-24, 2027 | P24: Salt Lake City, Utah, USA | Q24: 线下 | R24: 必须到场 | S24: 待确认 | T24: 不限 | U24: — | V24: 无专属条款 | W24: 已核实 | X24: — | Y24: https://ppopp27.sigplan.org/ | Z24: 与 PPoPP 同期常有 CGO/HPCA 等联办；核查:通知日2026-10-26临近；官网首页未列日期
A25: 24 | B25: CHI | C25: ACM Conference on Human Factors in Computing Systems | D25: 人机交互第一大会，交互技术/用户研究/可访问性全覆盖，重人本价值 | E25: 人机交互与普适计算 | F25: A | G25: — | H25: 46276.833 | I25: 单轮 | J25: AoE | K25: 46360.833 | L25: 2026-12-17 | M25: =IF(ISNUMBER(H25),IF(H25>'_轮次'!$A$1,"未截止","已截止"),"TBD") | N25: =IF(ISNUMBER(H25),IF(H25>'_轮次'!$A$1,INT(H25-'_轮次'!$A$1),"—"),"—") | O25: May 10 - 14, 2027 | P25: David L. Lawrence Convention Center, Pittsburgh, USA | Q25: 线下 | R25: 允许远程 | S25: 可交预录视频代替现场 | T25: 不限 | U25: — | V25: 硬性｜每篇须提名4人次审稿（RRP），须满足最低审稿资格 | W25: 已核实 | X25: — | Y25: https://chi2027.acm.org/ | Z25: 投稿系统为 PCS，非常见四类系统；核查:至少一位作者须2027-03-04前注册
A26: 25 | B26: UbiComp/ISWC | C26: ACM International Joint Conference on Pervasive and Ubiquitous Computing | D26: 普适计算旗舰，可穿戴/传感/情境感知与移动健康，重真实场景部署 | E26: 人机交互与普适计算 | F26: A | G26: — | H26: 待公布 | I26: — | J26: AoE | K26: — | L26: 待公布 | M26: =IF(ISNUMBER(H26),IF(H26>'_轮次'!$A$1,"未截止","已截止"),"TBD") | N26: =IF(ISNUMBER(H26),IF(H26>'_轮次'!$A$1,INT(H26-'_轮次'!$A$1),"—"),"—") | O26: October 3-7, 2027 | P26: Seoul, Republic of Korea | Q26: 线下 | R26: 待确认 | S26: 待确认 | T26: 不限 | U26: — | V26: CFP未发布 | W26: 2027CFP未发布 | X26: 截稿日、是否到场、新人条款 | Y26: https://sigchi.org/events/ubicomp-2027/ | Z26: 论文经 PACM IMWUT 期刊通道录用；核查:官网仅公布会期2027-10-03至10-07，无CFP
A27: 26 | B27: WWW | C27: International World Wide Web Conferences | D27: 万维网旗舰会，信息检索/推荐/图挖掘/Web 系统，重数据规模与在线效果 | E27: 交叉/综合/新兴 | F27: A | G27: 46314.833 | H27: 46321.833 | I27: 单轮 | J27: AoE | K27: — | L27: 2027-01-04 | M27: =IF(ISNUMBER(H27),IF(H27>'_轮次'!$A$1,"未截止","已截止"),"TBD") | N27: =IF(ISNUMBER(H27),IF(H27>'_轮次'!$A$1,INT(H27-'_轮次'!$A$1),"—"),"—") | O27: May 10 - 14, 2027 | P27: Dublin, Ireland | Q27: 线下 | R27: 必须到场 | S27: 口头可酌情线上，海报须现场 | T27: 7 | U27: 每届 | V27: 硬性｜作者须加入审稿委员会并按时审稿，否则可被拒 | W27: 已核实 | X27: — | Y27: https://www2027.thewebconf.org/ | Z27: 分 research/industry 多个 track；核查:摘要2026-10-18；每类投稿每人限7篇
A28: 27 | B28: INFOCOM | C28: IEEE International Conference on Computer Communications | D28: 计算机网络两大顶会之一，协议/无线/数据中心网络，重建模分析与仿真 | E28: 计算机网络 | F28: A | G28: 46228.833 | H28: 46235.833 | I28: 单轮 | J28: AoE | K28: — | L28: 2026-12-08 | M28: =IF(ISNUMBER(H28),IF(H28>'_轮次'!$A$1,"未截止","已截止"),"TBD") | N28: =IF(ISNUMBER(H28),IF(H28>'_轮次'!$A$1,INT(H28-'_轮次'!$A$1),"—"),"—") | O28: May 24 - 27, 2027 | P28: Honolulu, HI, USA | Q28: 线下 | R28: 必须到场 | S28: 待确认 | T28: 不限 | U28: — | V28: 未找到 | W28: 已核实 | X28: 新人条款 | Y28: https://infocom2027.ieee-infocom.org/ | Z28: 使用 EDAS 投稿，分主会与 workshop；核查:摘要2026-07-24；早期拒稿通知2026-10-09
A29: 28 | B29: MobiCom | C29: ACM Annual International Conference On Mobile Computing And Networking | D29: 移动计算与无线网络顶会，移动系统/无线感知/蜂窝网络，重原型与实测 | E29: 计算机网络 | F29: A | G29: 46261.833 | H29: 46268.833 | I29: Summer Deadlines | J29: AoE | K29: 46333.833 | L29: 2026-11-19 | M29: =IF(ISNUMBER(H29),IF(H29>'_轮次'!$A$1,"未截止","已截止"),"TBD") | N29: =IF(ISNUMBER(H29),IF(H29>'_轮次'!$A$1,INT(H29-'_轮次'!$A$1),"—"),"—") | O29: Oct 18-22, 2027 | P29: TBD | Q29: 线下 | R29: 必须到场 | S29: 待确认 | T29: 不限 | U29: — | V29: 利好｜通道 ACM Student Research Competition（poster） | W29: 已核实 | X29: — | Y29: https://www.sigmobile.org/mobicom/2027/ | Z29: 举办地 TBD，一年一轮投稿；核查:夏季批次；摘要2026-08-26，冬季批次未定
A30: 29 | B30: NSDI | C30: USENIX Symposium on Networked Systems Design and Implementation | D30: 网络系统设计与实现顶会，数据中心/云网络/可编程网络，重真实部署 | E30: 计算机网络 | F30: A | G30: =IF(ISNUMBER(H30),IF(N(INDEX('_轮次'!$N$30:$Y$30,MATCH(H30,'_轮次'!$B$30:$M$30,0)))=0,"—",INDEX('_轮次'!$N$30:$Y$30,MATCH(H30,'_轮次'!$B$30:$M$30,0))),"—") | H30: =IF(COUNT('_轮次'!$B$30:$M$30)=0,"待公布",IF(COUNTIF('_轮次'!$B$30:$M$30,">"&'_轮次'!$A$1)>0,SMALL('_轮次'!$B$30:$M$30,COUNTIF('_轮次'!$B$30:$M$30,"<="&'_轮次'!$A$1)+1),MAX('_轮次'!$B$30:$M$30))) | I30: =IF(ISNUMBER(H30),INDEX('_轮次'!$AX$30:$BI$30,MATCH(H30,'_轮次'!$B$30:$M$30,0)),"—") | J30: UTC-4 | K30: =IF(ISNUMBER(H30),IF(N(INDEX('_轮次'!$Z$30:$AK$30,MATCH(H30,'_轮次'!$B$30:$M$30,0)))=0,"—",INDEX('_轮次'!$Z$30:$AK$30,MATCH(H30,'_轮次'!$B$30:$M$30,0))),"—") | L30: =IF(ISNUMBER(H30),IF(N(INDEX('_轮次'!$AL$30:$AW$30,MATCH(H30,'_轮次'!$B$30:$M$30,0)))=0,"—",INDEX('_轮次'!$AL$30:$AW$30,MATCH(H30,'_轮次'!$B$30:$M$30,0))),"—") | M30: =IF(ISNUMBER(H30),IF(H30>'_轮次'!$A$1,"未截止","已截止"),"TBD") | N30: =IF(ISNUMBER(H30),IF(H30>'_轮次'!$A$1,INT(H30-'_轮次'!$A$1),"—"),"—") | O30: May 11-13, 2027 | P30: Providence, RI, USA | Q30: 线下 | R30: 必须到场 | S30: 未提供线上参会 | T30: 8 | U30: 每届 | V30: 利好｜每篇须一名作者全价注册（非学生价） | W30: 已核实 | X30: — | Y30: https://www.usenix.org/conference/nsdi27 | Z30: 春秋两轮投稿；核查:两轮制，秋季轮全文9/17；须全价注册现场报告；全部轮次 轮:2026-04-24 / 轮:2026-09-18
A31: 30 | B31: SIGCOMM | C31: ACM International Conference on Applications, Technologies, Architectures, and Protocols for Computer Communication | D31: 数据通信第一会，网络架构/协议/可编程数据平面，重测量与现网部署 | E31: 计算机网络 | F31: A | G31: — | H31: 46421.833 | I31: 单轮 | J31: AoE | K31: — | L31: 待公布 | M31: =IF(ISNUMBER(H31),IF(H31>'_轮次'!$A$1,"未截止","已截止"),"TBD") | N31: =IF(ISNUMBER(H31),IF(H31>'_轮次'!$A$1,INT(H31-'_轮次'!$A$1),"—"),"—") | O31: August 8 - 12, 2027 | P31: Bangkok, Thailand | Q31: 线下 | R31: 必须到场 | S31: 设远程 pod，报告仍须到场 | T31: 8 | U31: 每届 | V31: 硬性｜每篇须报一名互惠审稿作者，一般须具博士学位 | W31: 已核实 | X31: — | Y31: https://conferences.sigcomm.org/sigcomm/2027/ | Z31: 分两个投稿轮次，重 artifact 评估；核查:单轮；未公布录用通知日；无 rebuttal
A32: 31 | B32: CCS | C32: ACM Conference on Computer and Communications Security | D32: 安全四大顶会之一，系统安全/密码应用/隐私与机器学习安全，覆盖最广 | E32: 网络与信息安全 | F32: A | G32: — | H32: 待公布 | I32: — | J32: AoE | K32: — | L32: 待公布 | M32: =IF(ISNUMBER(H32),IF(H32>'_轮次'!$A$1,"未截止","已截止"),"TBD") | N32: =IF(ISNUMBER(H32),IF(H32>'_轮次'!$A$1,INT(H32-'_轮次'!$A$1),"—"),"—") | O32: October 11-15, 2027 | P32: Atlanta, USA | Q32: 线下 | R32: 必须到场 | S32: 待确认 | T32: 不限 | U32: — | V32: CFP未发布 | W32: 2027CFP未发布 | X32: 截稿日、新人条款 | Y32: https://www.sigsac.org/ccs/CCS2027/ | Z32: 两轮评审制，投稿量大；核查:官网仅有会期地点，无 CFP 内容
A33: 32 | B33: EUROCRYPT | C33: European Cryptology Conference | D33: 密码学三大顶会之一，偏理论：公钥密码/多方计算/零知识证明 | E33: 网络与信息安全 | F33: A | G33: — | H33: 46283.833 | I33: 单轮 | J33: AoE | K33: 46362.833 | L33: 2027-01-18 | M33: =IF(ISNUMBER(H33),IF(H33>'_轮次'!$A$1,"未截止","已截止"),"TBD") | N33: =IF(ISNUMBER(H33),IF(H33>'_轮次'!$A$1,INT(H33-'_轮次'!$A$1),"—"),"—") | O33: April 11-15, 2027 | P33: Eindhoven, Netherlands | Q33: 线下 | R33: 必须到场 | S33: 不设线上通道 | T33: 不限 | U33: — | V33: 无专属条款 | W33: 已核实 | X33: — | Y33: https://eurocrypt.iacr.org/2027/ | Z33: IACR 旗下，用 IACR 投稿服务器；核查:须由作者之一现场报告；论文录制
A34: 33 | B34: NDSS | C34: Network and Distributed System Security (NDSS) Symposium | D34: 安全四大顶会之一，网络与分布式系统安全，重攻击实现与大规模实测 | E34: 网络与信息安全 | F34: A | G34: =IF(ISNUMBER(H34),IF(N(INDEX('_轮次'!$N$34:$Y$34,MATCH(H34,'_轮次'!$B$34:$M$34,0)))=0,"—",INDEX('_轮次'!$N$34:$Y$34,MATCH(H34,'_轮次'!$B$34:$M$34,0))),"—") | H34: =IF(COUNT('_轮次'!$B$34:$M$34)=0,"待公布",IF(COUNTIF('_轮次'!$B$34:$M$34,">"&'_轮次'!$A$1)>0,SMALL('_轮次'!$B$34:$M$34,COUNTIF('_轮次'!$B$34:$M$34,"<="&'_轮次'!$A$1)+1),MAX('_轮次'!$B$34:$M$34))) | I34: =IF(ISNUMBER(H34),INDEX('_轮次'!$AX$34:$BI$34,MATCH(H34,'_轮次'!$B$34:$M$34,0)),"—") | J34: UTC-12 | K34: =IF(ISNUMBER(H34),IF(N(INDEX('_轮次'!$Z$34:$AK$34,MATCH(H34,'_轮次'!$B$34:$M$34,0)))=0,"—",INDEX('_轮次'!$Z$34:$AK$34,MATCH(H34,'_轮次'!$B$34:$M$34,0))),"—") | L34: =IF(ISNUMBER(H34),IF(N(INDEX('_轮次'!$AL$34:$AW$34,MATCH(H34,'_轮次'!$B$34:$M$34,0)))=0,"—",INDEX('_轮次'!$AL$34:$AW$34,MATCH(H34,'_轮次'!$B$34:$M$34,0))),"—") | M34: =IF(ISNUMBER(H34),IF(H34>'_轮次'!$A$1,"未截止","已截止"),"TBD") | N34: =IF(ISNUMBER(H34),IF(H34>'_轮次'!$A$1,INT(H34-'_轮次'!$A$1),"—"),"—") | O34: March 22 - March 26, 2027 | P34: Seoul, Republic of Korea | Q34: 线下 | R34: 必须到场 | S34: 待确认 | T34: 6 | U34: 每轮 | V34: 硬性｜配额 6 篇/周期（每位作者各自计，适用于所有作者） | W34: 已核实 | X34: — | Y34: https://www.ndss-symposium.org/ndss2027/ | Z34: 两轮投稿，夏季/秋季各一轮；核查:夏/秋两轮均截止；仅称须按参会政策报告；全部轮次 Summer:2026-05-07 / Fall:2026-08-20
A35: 34 | B35: S&P | C35: IEEE Symposium on Security and Privacy | D35: IEEE 安全旗舰，系统安全/隐私保护/密码应用，审稿严、录用率低 | E35: 网络与信息安全 | F35: A | G35: =IF(ISNUMBER(H35),IF(N(INDEX('_轮次'!$N$35:$Y$35,MATCH(H35,'_轮次'!$B$35:$M$35,0)))=0,"—",INDEX('_轮次'!$N$35:$Y$35,MATCH(H35,'_轮次'!$B$35:$M$35,0))),"—") | H35: =IF(COUNT('_轮次'!$B$35:$M$35)=0,"待公布",IF(COUNTIF('_轮次'!$B$35:$M$35,">"&'_轮次'!$A$1)>0,SMALL('_轮次'!$B$35:$M$35,COUNTIF('_轮次'!$B$35:$M$35,"<="&'_轮次'!$A$1)+1),MAX('_轮次'!$B$35:$M$35))) | I35: =IF(ISNUMBER(H35),INDEX('_轮次'!$AX$35:$BI$35,MATCH(H35,'_轮次'!$B$35:$M$35,0)),"—") | J35: UTC-12 | K35: =IF(ISNUMBER(H35),IF(N(INDEX('_轮次'!$Z$35:$AK$35,MATCH(H35,'_轮次'!$B$35:$M$35,0)))=0,"—",INDEX('_轮次'!$Z$35:$AK$35,MATCH(H35,'_轮次'!$B$35:$M$35,0))),"—") | L35: =IF(ISNUMBER(H35),IF(N(INDEX('_轮次'!$AL$35:$AW$35,MATCH(H35,'_轮次'!$B$35:$M$35,0)))=0,"—",INDEX('_轮次'!$AL$35:$AW$35,MATCH(H35,'_轮次'!$B$35:$M$35,0))),"—") | M35: =IF(ISNUMBER(H35),IF(H35>'_轮次'!$A$1,"未截止","已截止"),"TBD") | N35: =IF(ISNUMBER(H35),IF(H35>'_轮次'!$A$1,INT(H35-'_轮次'!$A$1),"—"),"—") | O35: May 17-19, 2027 | P35: MONTREAL, CANADA | Q35: 线下 | R35: 必须到场 | S35: 待确认 | T35: 6 | U35: 每轮 | V35: 硬性｜配额 每位作者每轮最多 6 篇（适用于所有作者） | W35: 已核实 | X35: — | Y35: https://sp2027.ieee-security.org/index.html | Z35: 两轮评审，周期长，常需 rebuttal；核查:官网无 CFP 正文，cfp.html 返回 404；重查:2027 CFP 已上线，第二轮 2026-11-17 截稿；每人每轮≤6 篇；全部轮次 First Paper submission deadline:2026-06-12 / Second Paper submission deadline:2026-11-18
A36: 35 | B36: USENIX Security | C36: USENIX Security Symposium | D36: 安全四大顶会之一，以系统安全与漏洞挖掘为主，重真实威胁实证 | E36: 网络与信息安全 | F36: A | G36: =IF(ISNUMBER(H36),IF(N(INDEX('_轮次'!$N$36:$Y$36,MATCH(H36,'_轮次'!$B$36:$M$36,0)))=0,"—",INDEX('_轮次'!$N$36:$Y$36,MATCH(H36,'_轮次'!$B$36:$M$36,0))),"—") | H36: =IF(COUNT('_轮次'!$B$36:$M$36)=0,"待公布",IF(COUNTIF('_轮次'!$B$36:$M$36,">"&'_轮次'!$A$1)>0,SMALL('_轮次'!$B$36:$M$36,COUNTIF('_轮次'!$B$36:$M$36,"<="&'_轮次'!$A$1)+1),MAX('_轮次'!$B$36:$M$36))) | I36: =IF(ISNUMBER(H36),INDEX('_轮次'!$AX$36:$BI$36,MATCH(H36,'_轮次'!$B$36:$M$36,0)),"—") | J36: UTC-12 | K36: =IF(ISNUMBER(H36),IF(N(INDEX('_轮次'!$Z$36:$AK$36,MATCH(H36,'_轮次'!$B$36:$M$36,0)))=0,"—",INDEX('_轮次'!$Z$36:$AK$36,MATCH(H36,'_轮次'!$B$36:$M$36,0))),"—") | L36: =IF(ISNUMBER(H36),IF(N(INDEX('_轮次'!$AL$36:$AW$36,MATCH(H36,'_轮次'!$B$36:$M$36,0)))=0,"—",INDEX('_轮次'!$AL$36:$AW$36,MATCH(H36,'_轮次'!$B$36:$M$36,0))),"—") | M36: =IF(ISNUMBER(H36),IF(H36>'_轮次'!$A$1,"未截止","已截止"),"TBD") | N36: =IF(ISNUMBER(H36),IF(H36>'_轮次'!$A$1,INT(H36-'_轮次'!$A$1),"—"),"—") | O36: August 11-13, 2027 | P36: Denver, CO, USA | Q36: 线下 | R36: 必须到场 | S36: 未提供线上参会 | T36: 7 | U36: 每轮 | V36: 硬性｜配额 7 篇/周期（每位作者各自计，适用于所有作者） | W36: 已核实 | X36: — | Y36: https://www.usenix.org/conference/usenixsecurity27 | Z36: 每年两轮截稿，秋季与春季各一次；核查:两轮制，取第2轮；须全价注册现场报告；全部轮次 Cycle 1 Deadline:2026-08-26 / Cycle 2 Deadline:2027-01-27
A37: 36 | B37: FM | C37: International Symposium on Formal Methods | D37: 形式化方法旗舰会议，聚焦建模验证、定理证明与工业级应用 | E37: 软件工程/系统软件 | F37: A | G37: — | H37: 待公布 | I37: — | J37: AoE | K37: — | L37: 待公布 | M37: =IF(ISNUMBER(H37),IF(H37>'_轮次'!$A$1,"未截止","已截止"),"TBD") | N37: =IF(ISNUMBER(H37),IF(H37>'_轮次'!$A$1,INT(H37-'_轮次'!$A$1),"—"),"—") | O37: October 18-22, 2027 | P37: Athens, Greece | Q37: 线下 | R37: 必须到场 | S37: 不设线上通道 | T37: 不限 | U37: — | V37: CFP未发布 | W37: 2027CFP未发布 | X37: 截稿日、新人条款 | Y37: https://www.fmeurope.org/feature/upcoming_conferences/ | Z37: 核查:FME 仅列 FM 2027 会期 18-22 Oct 2027 Athens，无截稿日
A38: 37 | B38: FSE | C38: ACM International Conference on the Foundations of Software Engineering | D38: 软件工程两大顶会之一，重方法创新与真实工程场景实证 | E38: 软件工程/系统软件 | F38: A | G38: — | H38: 46298.833 | I38: 单轮 | J38: AoE | K38: 46375.833 | L38: 2027-01-22 | M38: =IF(ISNUMBER(H38),IF(H38>'_轮次'!$A$1,"未截止","已截止"),"TBD") | N38: =IF(ISNUMBER(H38),IF(H38>'_轮次'!$A$1,INT(H38-'_轮次'!$A$1),"—"),"—") | O38: July 12-16, 2027 | P38: Shenzhen, China | Q38: 线下 | R38: 必须到场 | S38: 不设线上通道 | T38: 不限 | U38: — | V38: 未找到 | W38: 已核实 | X38: 新人条款 | Y38: https://conf.researchr.org/home/fse-2027 | Z38: 2027 届在深圳举办，国内投稿便利；核查:初审2027-01-22，大修改终审2027-03-31
A39: 38 | B39: ICSE | C39: International Conference on Software Engineering | D39: 软件工程第一大会，覆盖需求到测试全流程，看重实证与影响力 | E39: 软件工程/系统软件 | F39: A | G39: 46197.833 | H39: 46204.833 | I39: Single Submission Cycle Deadline | J39: AoE | K39: 46291.833 | L39: 2026-10-20 | M39: =IF(ISNUMBER(H39),IF(H39>'_轮次'!$A$1,"未截止","已截止"),"TBD") | N39: =IF(ISNUMBER(H39),IF(H39>'_轮次'!$A$1,INT(H39-'_轮次'!$A$1),"—"),"—") | O39: April 25-May 01, 2027 | P39: Dublin, Ireland | Q39: 线下 | R39: 必须到场 | S39: 不设线上通道 | T39: 不限 | U39: — | V39: 未找到 | W39: 已核实 | X39: 新人条款 | Y39: https://conf.researchr.org/home/icse-2027 | Z39: 核查:摘要2026-06-23；大修改论文终审2026-12-18
A40: 39 | B40: ISSTA | C40: ACM SIGSOFT International Symposium on Software Testing and Analysis | D40: 软件测试与分析顶会，偏动态分析、模糊测试与缺陷定位 | E40: 软件工程/系统软件 | F40: A | G40: 46396.833 | H40: 46399.833 | I40: 单轮 | J40: AoE | K40: 46472.833 | L40: 2027-04-20 | M40: =IF(ISNUMBER(H40),IF(H40>'_轮次'!$A$1,"未截止","已截止"),"TBD") | N40: =IF(ISNUMBER(H40),IF(H40>'_轮次'!$A$1,INT(H40-'_轮次'!$A$1),"—"),"—") | O40: September 7-10, 2027 | P40: Singapore | Q40: 线下 | R40: 必须到场 | S40: 不设线上通道 | T40: 不限 | U40: — | V40: 未找到 | W40: 已核实 | X40: 新人条款 | Y40: https://conf.researchr.org/home/issta-2027 | Z40: 常与 ECOOP 等会议联合举办；核查:强制摘要2027-01-08；终审2027-06-17
...

Sheet 扩展规则
A1: 序号 | B1: 简称 | C1: CCF | D1: 页数限制 | E1: 盲审 | F1: 投稿系统 | G1: CORE | H1: THCPL | I1: 作者投稿上限（原文） | J1: 官网核查 | K1: 核查依据 | L1: 备注
A2: 1 | B2: AAAI | C2: A | D2: 7 页正文 + refs | E2: 双盲 | F2: OpenReview | G2: A* | H2: A | I2: 不限 | J2: 已核实 | K2: https://aaai.org/conference/aaai/aaai-27/ | L2: 近年投稿量极大，录取率约 20% 上下；核查:摘要07-21，全文07-28；日程页未写宣讲与远程政策
A3: 2 | B3: ACL | C3: A | D3: 8 页长文 / 4 页短文 + refs | E3: 双盲 | F3: OpenReview | G3: A* | H3: A | I3: 不限 | J3: 已核实 | K3: https://2027.aclweb.org/calls/main/ | L3: 经 ACL Rolling Review 提交，再承诺至会议；核查:须至少一位作者注册并宣讲；录用通知日TBD
A4: 3 | B4: CVPR | C4: A | D4: 8 页 + refs | E4: 双盲 | F4: OpenReview | G4: A* | H4: A | I4: 不限 | J4: 已核实 | K4: https://cvpr.thecvf.com/Conferences/2027/CallForPapers | L4: 每年 11 月截稿，6 月开会；核查:论文注册11-10；CFP未明写现场宣讲要求
A5: 4 | B5: ICCV | C5: A | D5: 8 页 + refs | E5: 双盲 | F5: OpenReview | G5: A* | H5: A | I5: 不限 | J5: 2027CFP未发布 | K5: https://iccv.thecvf.com/Conferences/2027 | L5: 奇数年举办，2027 届正常召开；核查:官网仅公布时间地点(10/3-7)，CFP未出
A6: 5 | B6: ICLR | C6: A | D6: 9 页正文 + refs/附录 | E6: 双盲 | F6: OpenReview | G6: A* | H6: A | I6: 20 篇 | J6: 已核实 | K6: https://iclr.cc/Conferences/2027/AuthorGuidelines | L6: 评审意见与讨论全程公开；核查:署名≥3篇须审6篇；出席形式未明示
A7: 6 | B7: ACM SIGGRAPH | C7: A | D7: 待确认 | E7: 待确认 | F7: 官网自建 | G7: A* | H7: A | I7: 不限 | J7: 2027CFP未发布 | K7: https://s2027.siggraph.org/ | L7: 分技术论文与 Art Papers 等多轨道；核查:第三方站点称Stage1为2027-01-21，官网未见
A8: 7 | B8: IEEE VR | C8: A | D8: 8 页 + refs | E8: 双盲 | F8: OpenReview | G8: A* | H8: A | I8: 不限 | J8: 已核实 | K8: https://ieeevr.org/2027/contribute/papers | L8: 期刊轨与会议轨并行，TVCG 出版；核查:截稿已过(2026-08-31)；资深作者须任审稿人
A9: 8 | B9: CAV | C9: A | D9: 待确认 | E9: 单盲 | F9: 待确认 | G9: A* | H9: A | I9: 5 篇 | J9: 已核实 | K9: https://conferences.i-cav.org/2027/cfp/ | L9: LNCS 出版，另设 artifact 评审；核查:全文2027-01-20；每作者限投5篇（含三类）
A10: 9 | B10: LICS | C10: A | D10: 待确认 | E10: 单盲 | F10: 待确认 | G10: A* | H10: A | I10: 不限 | J10: 2027CFP未发布 | K10: https://lics.siglog.org/lics27/ | L10: 常与 ICALP 等逻辑类会议联办；核查:官网仅占位页，注明信息稍后公布
A11: 10 | B11: SODA | C11: A | D11: 待确认 | E11: 单盲 | F11: EasyChair | G11: A* | H11: A | I11: 不限 | J11: 已核实 | K11: https://www.siam.org/conferences-events/siam-conferences/soda27/submissions/ | L11: 与 ALENEX/ANALCO 同期同地举办；核查:录用通知仅写2026年10月，无具体日
A12: 11 | B12: STOC | C12: A | D12: 待确认 | E12: 单盲 | F12: 待确认 | G12: A* | H12: A | I12: 5 篇 | J12: 已核实 | K12: https://acm-stoc.org/stoc2027/stoc2027-cfp.html | L12: 与 FOCS 并列为理论两大顶会；核查:强制公开发布投稿并提交20-30分钟视频
A13: 12 | B13: ICDE | C13: A | D13: 6 页 + refs | E13: 待确认 | F13: 待确认 | G13: A* | H13: A | I13: 不限 | J13: 已核实 | K13: https://icde2027.github.io/important-dates.html | L13: IEEE 主办，分研究轨与工业轨；核查:研究主会两轮，第一轮2026-06-11已截；全部轮次 first round:2026-06-12 / second round:2026-11-12
... A201: 200 | B201: SATML | C201: N | D201: 待确认 | E201: 双盲 | F201: OpenReview | G201: N | H201: N | I201: 不限 | J201: 已核实 | K201: https://satml.org/call-for-papers | L201: IEEE 主办，安全与ML交叉，含竞赛 track；核查:摘要注册2026-09-22必填

Sheet 新人作者要求
A1: 序号 | B1: 简称 | C1: CCF | D1: 方向 | E1: 条款状态 | F1: 对首投的影响 | G1: 首投可投篇数 | H1: 审稿义务 / 互惠审稿 | I1: 首投配额 | J1: 资深作者要求 | K1: 投稿账号门槛 | L1: 学生 / 新人通道 | M1: 费用与资助 | N1: 依据 URL | O1: 置信度 | P1: 备注
A2: 1 | B2: AAAI | C2: A | D2: 人工智能 | E2: 未找到 | F2: 未找到 | G2: 不限 | H2: 未找到 | I2: 未找到 | J2: 待确认 | K2: 未找到 | L2: 未找到 | M2: 未找到 | N2: https://aaai.org/conference/aaai/aaai-27/ | O2: 低 | P2: 站点仅发布日程；作者政策页重定向至往届 AAAI-25
A3: 2 | B3: ACL | C3: A | D3: 人工智能 | E3: 未找到 | F3: 未找到 | G3: 不限 | H3: 未找到 | I3: 未找到 | J3: 待确认 | K3: 未找到 | L3: 未找到 | M3: 未找到 | N3: https://2027.aclweb.org/calls/main/ | O3: 低 | P3: 站点仅上线主会 CFP；审稿与 SRW 政策走 ARR，未发布
A4: 3 | B4: CVPR | C4: A | D4: 人工智能 | E4: 有专属条款 | F4: 有硬性要求 | G4: 不限 | H4: 全体作者须应召担任审稿人，豁免须事前申请 | I4: 无 | J4: 不强制 | K4: 需 OpenReview 档案；无机构邮箱审核约 2 周 | L4: 无 | M4: 未提及 | N4: https://cvpr.thecvf.com/Conferences/2027/CallForPapers | O4: 高 | P4: Mandatory Reviewer Service，依 PAMI 技术委员会指引
A5: 4 | B5: ICCV | C5: A | D5: 人工智能 | E5: CFP未发布 | F5: CFP未发布 | G5: CFP未发布 | H5: CFP未发布 | I5: CFP未发布 | J5: CFP未发布 | K5: CFP未发布 | L5: CFP未发布 | M5: CFP未发布 | N5: — | O5: 高
A6: 5 | B6: ICLR | C6: A | D6: 人工智能 | E6: 有专属条款 | F6: 有硬性要求 | G6: 1 篇（无合格互惠审稿人时）；全体上限 20 篇/届 | H6: 须指定作者注册审稿≥3 篇，否则直接拒稿 | I6: 1 篇（无合格互惠审稿人时） | J6: 不强制 | K6: 须 OpenReview 档案；无机构邮箱审核约 2 周 | L6: 无 | M6: 未提及 | N6: https://iclr.cc/Conferences/2027/AuthorGuidelines | O6: 高 | P6: 单人最多 20 篇；3 篇以上作者须审 ≥6 篇
A7: 6 | B7: ACM SIGGRAPH | C7: A | D7: 图形学与多媒体 | E7: CFP未发布 | F7: CFP未发布 | G7: CFP未发布 | H7: CFP未发布 | I7: CFP未发布 | J7: CFP未发布 | K7: CFP未发布 | L7: CFP未发布 | M7: CFP未发布 | N7: — | O7: 高
A8: 7 | B8: IEEE VR | C8: A | D8: 图形学与多媒体 | E8: 有专属条款 | F8: 有硬性要求 | G8: 不限 | H8: 资深作者须注册审稿，评审数≥投稿数，失责可拒稿 | I8: 无 | J8: 不强制 | K8: 走 PCS 投稿；资深作者须在 PCS 注册审稿 | L8: 无 | M8: 未提及 | N8: https://ieeevr.org/2027/contribute/papers | O8: 高 | P8: 资深=有 PhD 或同等资历；无资深作者亦须指派人
A9: 8 | B9: CAV | C9: A | D9: 计算机科学理论 | E9: 无专属条款 | F9: 无 | G9: 5 篇/届 | H9: 无审稿义务 | I9: 无 | J9: 不强制 | K9: 无门槛 | L9: 无 | M9: 未提及 | N9: https://conferences.i-cav.org/2027/cfp/ | O9: 中 | P9: 仅全体作者统一 5 篇上限，无新人专属条款
A10: 9 | B10: LICS | C10: A | D10: 计算机科学理论 | E10: CFP未发布 | F10: CFP未发布 | G10: CFP未发布 | H10: CFP未发布 | I10: CFP未发布 | J10: CFP未发布 | K10: CFP未发布 | L10: CFP未发布 | M10: CFP未发布 | N10: — | O10: 高
A11: 10 | B11: SODA | C11: A | D11: 计算机科学理论 | E11: 有专属条款 | F11: 只有利好通道 | G11: 不限 | H11: 无审稿义务 | I11: 无 | J11: 不强制 | K11: 无门槛 | L11: 最佳学生论文奖（全学生作者可评） | M11: SIAM 通用差旅资助，10/26 截止 | N11: https://www.siam.org/conferences-events/siam-conferences/soda27/submissions/ | O11: 中 | P11: 无页数限制；学生相关活动见 Special Events 页
A12: 11 | B12: STOC | C12: A | D12: 计算机科学理论 | E12: 有专属条款 | F12: 有硬性要求 | G12: 5 篇/届 | H12: 无审稿义务 | I12: 5 篇（每位作者各自计，适用于所有作者） | J12: 不强制 | K12: 录用后须 ORCID ID | L12: 最佳学生论文奖（Danny Lewin） | M12: SIGACT 学生及发展中国家差旅资助 | N12: https://acm-stoc.org/stoc2027/stoc2027-cfp.html | O12: 高 | P12: 非匿名评审；作者须为人类
A13: 12 | B13: ICDE | C13: A | D13: 数据库/数据挖掘 | E13: 有专属条款 | F13: 有硬性要求 | G13: 5 篇（每轮，研究轨道） | H13: 无审稿义务 | I13: 5 篇（每轮，研究轨道） | J13: 不强制 | K13: 全体作者须 ORCID 及 CMT 档案，缺则拒稿 | L13: Ph.D. Symposium | M13: 未提及 | N13: https://icde2027.github.io/submission-guidelines.html | O13: 高 | P13: 两轮投稿，每轮只给接受/拒绝，无修订
A14: 13 | B14: SIGIR | C14: A | D14: 数据库/数据挖掘 | E14: 有专属条款 | F14: 只有利好通道 | G14: 不限 | H14: 未找到 | I14: 未找到 | J14: 待确认 | K14: 未找到 | L14: Doctoral Consortium | M14: 学生及研究者 travel grants（50 周年） | N14: https://sigir2027.org/ | O14: 中 | P14: 论文 CFP 与审稿政策尚未上线，仅首页零散信息
A15: 14 | B15: SIGKDD | C15: A | D15: 数据库/数据挖掘 | E15: 有专属条款 | F15: 有硬性要求 | G15: 7 篇/届 | H15: 须提名 1 名合格审稿人（KDD 等≥3 篇） | I15: 7 篇（研究轨道，每周期） | J15: 不强制 | K15: 全体作者须完整 OpenReview 档案，缺则拒稿 | L15: 无 | M15: 未提及；注册须标准（非学生）价 | N15: https://kdd2027.kdd.org/research-track-call-for-papers/ | O15: 高 | P15: 档案须含机构、DBLP、ORCID、导师与论文
A16: 15 | B16: SIGMOD | C16: A | D16: 数据库/数据挖掘 | E16: 未找到 | F16: 未找到 | G16: 10 篇/届 | H16: 未找到 | I16: 未找到 | J16: 待确认 | K16: 未找到 | L16: 未找到 | M16: 未找到 | N16: https://2027.sigmod.org/calls_papers_important_dates.shtml | O16: 低 | P16: 仅有日程页；calls_papers 征稿政策页返回 404
A17: 16 | B17: VLDB | C17: A | D17: 数据库/数据挖掘 | E17: 有专属条款 | F17: 有硬性要求 | G17: 12 篇/年（每月≤2） | H17: 须提名 1 名合格审稿人（VLDB 等≥2 篇） | I17: 每月 2 篇，全年 12 篇 | J17: 不强制 | K17: 全体作者须 CMT 注册并申报冲突，否则拒稿 | L17: 无 | M17: 未提及 | N17: https://vldb.org/pvldb/volumes/20/submission | O17: 高 | P17: 提名审稿人失责，全体作者年上限各减 1 篇
A18: 17 | B18: ASPLOS | C18: A | D18: 体系结构/并行/存储 | E18: 无专属条款 | F18: 无 | G18: 4 篇/届 | H18: 无审稿义务 | I18: 无 | J18: 不强制 | K18: 无门槛 | L18: 无 | M18: 未提及 | N18: https://www.asplos-conference.org/asplos2027/cfp/ | O18: 高 | P18: CFP全文无A-F条款；仅全局限每人每周期4篇
A19: 18 | B19: DAC | C19: A | D19: 体系结构/并行/存储 | E19: 无专属条款 | F19: 无 | G19: 不限 | H19: 无审稿义务 | I19: 无 | J19: 不强制 | K19: 无门槛 | L19: 无 | M19: 未提及 | N19: https://dac.com/2027/authors/call-for-contributions | O19: 中 | P19: Tracks页与研究稿页均无新人/学生及审稿义务条款
A20: 19 | B20: EuroSys | C20: A | D20: 体系结构/并行/存储 | E20: 无专属条款 | F20: 无 | G20: 3 篇/届 | H20: 无审稿义务 | I20: 无 | J20: 不强制 | K20: 无门槛 | L20: 无 | M20: 未提及 | N20: https://2027.eurosys.org/cfp.html | O20: 高 | P20: CFP无A-F条款；仅全局限每人每周期3篇
A21: 20 | B21: FAST | C21: A | D21: 体系结构/并行/存储 | E21: 有专属条款 | F21: 只有利好通道 | G21: 不限 | H21: 无审稿义务 | I21: 无 | J21: 不强制 | K21: 无门槛 | L21: WIP/Posters、Mentoring（均设联合主席） | M21: 每篇须一名作者全价注册（非学生价） | N21: https://www.usenix.org/conference/fast27/call-for-papers | O21: 中 | P21: 无学生注册优惠；经济困难可邮件申请
A22: 21 | B22: HPCA | C22: A | D22: 体系结构/并行/存储 | E22: 有专属条款 | F22: 有硬性要求 | G22: 不限 | H22: 每篇须指定资深作者，或须任Light PC审稿≤6篇 | I22: 无 | J22: 必须挂资深作者 | K22: 无门槛 | L22: 无 | M22: 未提及 | N22: https://sigarch.org/call-contributions/hpca-2027 | O22: 高 | P22: 无资深作者将无人可被派审稿，属硬门槛
... A25: 24 | B25: CHI | C25: A | D25: 人机交互与普适计算 | E25: 有专属条款 | F25: 有硬性要求 | G25: 不限 | H25: 每篇须提名4人次审稿（RRP），须满足最低审稿资格 | I25: 无 | J25: 不强制 | K25: 须ORCID，PCS档案填DBLP，邮箱有效 | L25: 无 | M25: 未提及 | N25: https://chi2027.acm.org/authors/papers/ | O25: 高 | P25: 未达审稿资格者须靠资深合作者凑4份；作者名单冻结
A26: 25 | B26: UbiComp/ISWC | C26: A | D26: 人机交互与普适计算 | E26: CFP未发布 | F26: CFP未发布 | G26: CFP未发布 | H26: CFP未发布 | I26: CFP未发布 | J26: CFP未发布 | K26: CFP未发布 | L26: CFP未发布 | M26: CFP未发布 | N26: — | O26: 高
A27: 26 | B27: WWW | C27: A | D27: 交叉/综合/新兴 | E27: 有专属条款 | F27: 有硬性要求 | G27: 7 篇/届 | H27: 作者须加入审稿委员会并按时审稿，否则可被拒 | I27: 无 | J27: 不强制 | K27: 所有作者须完善OpenReview档案与COI | L27: 无 | M27: 论文须非学生标准现场注册，每篇一次 | N27: https://www2027.thewebconf.org/research-track-papers/ | O27: 高 | P27: 全局限每类投稿7篇；学生价不能覆盖论文
A28: 27 | B28: INFOCOM | C28: A | D28: 计算机网络 | E28: 未找到 | F28: 未找到 | G28: 不限 | H28: 未找到 | I28: 无 | J28: 待确认 | K28: 未找到 | L28: 未找到 | M28: 未提及 | N28: https://infocom2027.ieee-infocom.org/authors | O28: 低 | P28: Authors页仅列日期，CFP称细则另发，未见审稿/配额条款
A29: 28 | B29: MobiCom | C29: A | D29: 计算机网络 | E29: 有专属条款 | F29: 只有利好通道 | G29: 不限 | H29: 未找到 | I29: 无 | J29: 待确认 | K29: 未找到 | L29: ACM Student Research Competition（poster） | M29: 未提及 | N29: https://www.sigmobile.org/mobicom/2027/ | O29: 中 | P29: 仅主页可读，/cfp/与/call-for-papers/均404
A30: 29 | B30: NSDI | C30: A | D30: 计算机网络 | E30: 有专属条款 | F30: 只有利好通道 | G30: 8 篇/届 | H30: 无审稿义务 | I30: 无 | J30: 不强制 | K30: 无门槛 | L30: 无 | M30: 每篇须一名作者全价注册（非学生价） | N30: https://www.usenix.org/conference/nsdi27/call-for-papers | O30: 高 | P30: 学生无法用学生价覆盖论文；全局限8篇
A31: 30 | B31: SIGCOMM | C31: A | D31: 计算机网络 | E31: 有专属条款 | F31: 有硬性要求 | G31: 8 篇/届 | H31: 每篇须报一名互惠审稿作者，一般须具博士学位 | I31: 无 | J31: 不强制 | K31: 投稿须填ORCID | L31: 无 | M31: 未提及 | N31: https://conferences.sigcomm.org/sigcomm/2027/cfp/ | O31: 高 | P31: 无博士级互惠审稿人的独立作者最受限；全局限8篇
A32: 31 | B32: CCS | C32: A | D32: 网络与信息安全 | E32: CFP未发布 | F32: CFP未发布 | G32: CFP未发布 | H32: CFP未发布 | I32: CFP未发布 | J32: CFP未发布 | K32: CFP未发布 | L32: CFP未发布 | M32: CFP未发布 | N32: — | O32: 高
A33: 32 | B33: EUROCRYPT | C33: A | D33: 网络与信息安全 | E33: 无专属条款 | F33: 无 | G33: 不限 | H33: 无审稿义务 | I33: 无 | J33: 不强制 | K33: 无门槛 | L33: 无 | M33: 未提及 | N33: https://eurocrypt.iacr.org/2027/papersubmission.php | O33: 中 | P33: 通读投稿页：仅匿名、格式、COI要求，无A–F条款
A34: 33 | B34: NDSS | C34: A | D34: 网络与信息安全 | E34: 有专属条款 | F34: 有硬性要求 | G34: 6 篇/轮 | H34: 无审稿义务 | I34: 6 篇/周期（每位作者各自计，适用于所有作者） | J34: 不强制 | K34: 无门槛 | L34: 无 | M34: 未提及 | N34: https://www.ndss-symposium.org/ndss2027/submissions/call-for-papers/ | O34: 高 | P34: 单周期6篇、全年12篇，超额可desk reject
A35: 34 | B35: S&P | C35: A | D35: 网络与信息安全 | E35: 有专属条款 | F35: 有硬性要求 | G35: 6 篇/轮 | H35: 无审稿义务 | I35: 每位作者每轮最多 6 篇（适用于所有作者） | J35: 不强制 | K35: 摘要注册时须填全部作者 ORCID，邮箱须与 HotCRP 一致 | L35: 无 | M35: 设学生差旅资助（组委会设专职主席） | N35: https://sp2027.ieee-security.org/cfpapers.html | O35: 高 | P35: CFP 原文：Any author may submit no more than 6 papers per cycle
A36: 35 | B36: USENIX Security | C36: A | D36: 网络与信息安全 | E36: 有专属条款 | F36: 有硬性要求 | G36: 7 篇/轮 | H36: 无审稿义务 | I36: 7 篇/周期（每位作者各自计，适用于所有作者） | J36: 不强制 | K36: 全员须配 ORCID 并确认投稿条款 | L36: 无 | M36: 报告者须全价注册，困难可申请减免 | N36: https://www.usenix.org/conference/usenixsecurity27/call-for-papers | O36: 高 | P36: 超7篇保留投稿号最小的7篇；学生价不满足报告义务
A37: 36 | B37: FM | C37: A | D37: 软件工程/系统软件 | E37: CFP未发布 | F37: CFP未发布 | G37: CFP未发布 | H37: CFP未发布 | I37: CFP未发布 | J37: CFP未发布 | K37: CFP未发布 | L37: CFP未发布 | M37: CFP未发布 | N37: — | O37: 高
A38: 37 | B38: FSE | C38: A | D38: 软件工程/系统软件 | E38: 未找到 | F38: 未找到 | G38: 不限 | H38: 未找到 | I38: 未找到 | J38: 待确认 | K38: 未找到 | L38: 未找到 | M38: 未找到 | N38: https://conf.researchr.org/home/fse-2027 | O38: 低 | P38: evidence疑指向密码学FSE；本会Research Papers页需登录
A39: 38 | B39: ICSE | C39: A | D39: 软件工程/系统软件 | E39: 未找到 | F39: 未找到 | G39: 不限 | H39: 未找到 | I39: 未找到 | J39: 待确认 | K39: 未找到 | L39: 未找到 | M39: 未找到 | N39: https://conf.researchr.org/home/icse-2027 | O39: 低 | P39: Research Papers CFP返回404；首页仅见双盲与数据共享说明
A40: 39 | B40: ISSTA | C40: A | D40: 软件工程/系统软件 | E40: 未找到 | F40: 未找到 | G40: 不限 | H40: 未找到 | I40: 未找到 | J40: 待确认 | K40: 未找到 | L40: 未找到 | M40: 未找到 | N40: https://conf.researchr.org/track/issta-2027/issta-2027-research-papers | O40: 低 | P40: Research Papers 正文内容仍为 TBD，日期已公布
A41: 40 | B41: OOPSLA | C41: A | D41: 软件工程/系统软件 | E41: 有专属条款 | F41: 有硬性要求 | G41: 5 篇/轮（无资深作者者至多2篇）；全体上限 5 篇/届 | H41: 每篇须1名资深作者注册储备审稿人，否则可desk reject | I41: 5 篇/轮（无资深作者者至多2篇） | J41: 不强制 | K41: 储备审稿人须用HotCRP同邮箱在TPMS注册 | L41: 无 | M41: 未提及 | N41: https://2027.splashcon.org/track/splashoopsla2027 | O41: 高 | P41: 无资深作者、或资深者为SIGPLAN/SIGSOFT新人可豁免
A42: 41 | B42: OSDI | C42: A | D42: 软件工程/系统软件 | E42: 有专属条款 | F42: 有硬性要求 | G42: 8 篇/届 | H42: 无审稿义务 | I42: 8 篇（每位作者各自计，适用于所有作者） | J42: 不强制 | K42: 无门槛 | L42: 无 | M42: 未提及 | N42: https://www.usenix.org/conference/osdi27/call-for-papers | O42: 高 | P42: 超8篇由项目主席desk reject多余投稿
...

Sheet 待补清单
A1: 序号 | B1: 简称 | C1: CCF | D1: 状态 | E1: 剩余天数 (生成时) | F1: 缺什么 | G1: 缺口类型 | H1: 下一步 | I1: 官网核查 | J1: 官网
A2: 129 | B2: CVM | C2: C | D2: 未截止 | E2: 2 | F2: 是否到场、新人条款 | G2: 官网未写明 | H2: 查 Registration / Attending / FAQ / Reviewing 子页 | I2: 已核实 | J2: http://iccvm.org/2027/
A3: 83 | B3: ISCAS | C3: B | D3: 未截止 | E3: 2 | F3: 是否到场、新人条款 | G3: 等官方发布 | H3: 2027 CFP 未出，发布后重查；不要沿用上届 | I3: 2027CFP未发布 | J3: https://2027.ieee-iscas.org/
A4: 194 | B4: MLSys | C4: N | D4: 未截止 | E4: 5 | F4: 是否到场 | G4: 官网未写明 | H4: 查 Registration / Attending / FAQ / Reviewing 子页 | I4: 已核实 | J4: https://mlsys.org/
A5: 166 | B5: SACMAT | C5: C | D5: 未截止 | E5: 6 | F5: 新人条款 | G5: 等官方发布 | H5: 2027 CFP 未出，发布后重查；不要沿用上届 | I5: 2027CFP未发布 | J5: https://www.sacmat.org/2027/
A6: 143 | B6: CSCWD | C6: C | D6: 未截止 | E6: 7 | F6: 是否到场、新人条款 | G6: 官网未查到 | H6: 换入口重查（官网 / dblp / 主办方页面） | I6: 官网不可达 | J6: http://2027.cscwd.org
A7: 95 | B7: RECOMB | C7: B | D7: 未截止 | E7: 11 | F7: 是否到场、新人条款 | G7: 等官方发布 | H7: 2027 CFP 未出，发布后重查；不要沿用上届 | I7: 2027CFP未发布 | J7: https://recomb.org/recomb2027/
A8: 64 | B8: HSCC | C8: B | D8: 未截止 | E8: 12 | F8: 是否到场、新人条款 | G8: 官网未写明 | H8: 查 Registration / Attending / FAQ / Reviewing 子页 | I8: 已核实 | J8: https://hscc.acm.org/2027/
A9: 198 | B9: NOMS | C9: N | D9: 未截止 | E9: 16 | F9: 是否到场 | G9: 官网未写明 | H9: 查 Registration / Attending / FAQ / Reviewing 子页 | I9: 已核实 | J9: https://noms2027.ieee-noms.org/
A10: 133 | B10: PacificVis | C10: C | D10: 未截止 | E10: 16 | F10: 新人条款 | G10: 官网未查到 | H10: 换入口重查（官网 / dblp / 主办方页面） | I10: 未找到 | J10: https://pacificvis2027.github.io/
A11: 107 | B11: CAiSE | C11: B | D11: 未截止 | E11: 22 | F11: 是否到场、新人条款 | G11: 官网未写明 | H11: 查 Registration / Attending / FAQ / Reviewing 子页 | I11: 已核实 | J11: https://deal.us.es/caise27/
A12: 108 | B12: ECOOP | C12: B | D12: 未截止 | E12: 26 | F12: 是否到场 | G12: 官网未写明 | H12: 查 Registration / Attending / FAQ / Reviewing 子页 | I12: 已核实 | J12: https://2027.ecoop.org/
A13: 197 | B13: MMSys | C13: N | D13: 未截止 | E13: 26 | F13: 是否到场、新人条款 | G13: 官网未写明 | H13: 查 Registration / Attending / FAQ / Reviewing 子页 | I13: 已核实 | J13: https://2027.acmmmsys.org
... A62: 71 | B62: ICDM | C62: B | D62: 未截止 | E62: 225 | F62: 是否到场、新人条款 | G62: 官网未写明 | H62: 查 Registration / Attending / FAQ / Reviewing 子页 | I62: 已核实 | J62: https://icdm2027-website.onrender.com/
A63: 135 | B63: FSCD | C63: C | D63: TBD | E63: — | F63: 截稿日、是否到场 | G63: 官网未写明 | H63: 查 Registration / Attending / FAQ / Reviewing 子页 | I63: 已核实 | J63: https://fscd-cade.science.ru.nl/
A64: 54 | B64: EuroVis | C64: B | D64: TBD | E64: — | F64: 截稿日、是否到场、新人条款 | G64: 官网未查到 | H64: 换入口重查（官网 / dblp / 主办方页面） | I64: 未找到 | J64: https://eurovis27.github.io/web/
A65: 4 | B65: ICCV | C65: A | D65: TBD | E65: — | F65: 截稿日、新人条款 | G65: 等官方发布 | H65: 2027 CFP 未出，发布后重查；不要沿用上届 | I65: 2027CFP未发布 | J65: https://iccv.thecvf.com/Conferences/2027
A66: 6 | B66: ACM SIGGRAPH | C66: A | D66: TBD | E66: — | F66: 截稿日、新人条款 | G66: 等官方发布 | H66: 2027 CFP 未出，发布后重查；不要沿用上届 | I66: 2027CFP未发布 | J66: https://s2027.siggraph.org/
A67: 9 | B67: LICS | C67: A | D67: TBD | E67: — | F67: 截稿日、是否到场、新人条款 | G67: 等官方发布 | H67: 2027 CFP 未出，发布后重查；不要沿用上届 | I67: 2027CFP未发布 | J67: https://lics.siglog.org/lics27/
A68: 25 | B68: UbiComp/ISWC | C68: A | D68: TBD | E68: — | F68: 截稿日、是否到场、新人条款 | G68: 等官方发布 | H68: 2027 CFP 未出，发布后重查；不要沿用上届 | I68: 2027CFP未发布 | J68: https://sigchi.org/events/ubicomp-2027/
A69: 31 | B69: CCS | C69: A | D69: TBD | E69: — | F69: 截稿日、新人条款 | G69: 等官方发布 | H69: 2027 CFP 未出，发布后重查；不要沿用上届 | I69: 2027CFP未发布 | J69: https://www.sigsac.org/ccs/CCS2027/
A70: 36 | B70: FM | C70: A | D70: TBD | E70: — | F70: 截稿日、新人条款 | G70: 等官方发布 | H70: 2027 CFP 未出，发布后重查；不要沿用上届 | I70: 2027CFP未发布 | J70: https://www.fmeurope.org/feature/upcoming_conferences/
A71: 46 | B71: COLT | C71: B | D71: TBD | E71: — | F71: 截稿日、新人条款 | G71: 等官方发布 | H71: 2027 CFP 未出，发布后重查；不要沿用上届 | I71: 2027CFP未发布 | J71: https://learningtheory.org/colt2027/
A72: 60 | B72: SGP | C72: B | D72: TBD | E72: — | F72: 截稿日、是否到场、新人条款 | G72: 等官方发布 | H72: 2027 CFP 未出，发布后重查；不要沿用上届 | I72: 2027CFP未发布 | J72: https://igs2027singapore.github.io/
A73: 61 | B73: SPM | C73: B | D73: TBD | E73: — | F73: 截稿日、是否到场、新人条款 | G73: 等官方发布 | H73: 2027 CFP 未出，发布后重查；不要沿用上届 | I73: 2027CFP未发布 | J73: https://igs2027singapore.github.io/
A74: 63 | B74: CCC | C74: B | D74: TBD | E74: — | F74: 截稿日、是否到场、新人条款 | G74: 等官方发布 | H74: 2027 CFP 未出，发布后重查；不要沿用上届 | I74: 2027CFP未发布 | J74: https://computationalcomplexity.org/
... A113: 177 | B113: CVC | C113: N | D113: 已截止 | E113: — | F113: 是否到场、新人条款 | G113: 等官方发布 | H113: 2027 CFP 未出，发布后重查；不要沿用上届 | I113: 2027CFP未发布 | J113: https://saiconference.com/CVC

Sheet ARR 轮次
A1: ACL Rolling Review（ARR）滚动审稿轮次
A2: ARR 自 2025 年 5 月起改为 10 周一轮、每年约 5 轮，投稿日不再固定为每月某日。 数据源：https://aclrollingreview.org/dates（核对于 2026-10-25）
A4: Cycle | B4: 投稿截止 | C4: 审稿人注册 | D4: 审稿意见截止 | E4: 作者回复期 | F4: Meta-review 释出 | G4: Cycle 结束
A5: March 2026 | B5: 46097 | C5: 46099 | D5: 46132 | E5: 04-28 → 05-04 | F5: 46163 | G5: 46166
A6: May 2026 | B6: 46167 | C6: 46169 | D6: 46205 | E6: 07-08 → 07-14 | F6: 46233 | G6: 46236
A7: August 2026 | B7: 46237 | C7: 46239 | D7: 46272 | E7: 09-14 → 09-24 | F7: 46303 | G7: 46306
A8: October 2026 | B8: 46307 | C8: 46309 | D8: 46342 | E8: 11-24 → 11-30 | F8: 46373 | G8: 46376
A10: =IF(COUNTIF($B$5:$B$8,">="&TODAY())=0,"⚠ 表内各 ARR cycle 的投稿日均已过，请核对 https://aclrollingreview.org/dates 后更新 arr_cycles.json 并重新生成","最近一轮 ARR 投稿截止："&TEXT(SMALL($B$5:$B$8,COUNTIF($B$5:$B$8,"<"&TODAY())+1),"yyyy-mm-dd")&"（高亮行）")
A11: 官网提到 ACL 2027 对应 cycle 的投稿截止在 2027 年 1 月，但完整日期尚未列出；建议每月核对 aclrollingreview.org/dates。
A13: ARR 路径与可 commit 会议（2027 届）
A14: 会议 | B14: CCF | C14: 会期 / 地点 | D14: 路径 | E14: 最近一轮截稿(北京) | F14: 说明
A15: ACL | B15: A | C15: August 17-22, 2027 | Kyoto, Japan | D15: ARR Submission | E15: 2027-01-05 19:59 | F15: 先投 ARR 拿 meta-review，再 commit 到本会，非直接投稿
A16: COLING | B16: B | C16: May 9-14, 2027 | Macau SAR, China | D16: COLING commitment after ARR meta-reviews; reviewed papers only | E16: 2026-12-24 19:59 | F16: 先投 ARR 拿 meta-review，再 commit 到本会，非直接投稿
A17: NAACL | B17: B | C17: June 1-5, 2027 | San Francisco, California, USA | D17: NAACL commitment after ARR meta-reviews; reviewed papers only | E17: 2026-12-24 19:59 | F17: 先投 ARR 拿 meta-review，再 commit 到本会，非直接投稿
A18: EACL | B18: N | C18: March 9-14, 2027 | Athens, Greece | D18: EACL commitment after ARR meta-reviews; reviewed papers only | E18: 2026-10-12 19:59 | F18: 先投 ARR 拿 meta-review，再 commit 到本会，非直接投稿

Sheet 读我
A1: CCF 推荐会议 2027 届投稿规划表
A2: 生成时间 2026-10-25 05:12（北京） |覆盖 2027 届会议 200 个（A 43 · B 74 · C 58 · N 25） | 官网已核实 149 未发布 42 未查到 9 | 新人条款：有 79（其中硬性 43） 无 39 CFP未发布 42 未找到 40
A3: 电脑时区 (UTC±h) | B3: 8
A4: 换算后北京时间 | B4: =TEXT('_轮次'!$A$1,"yyyy-mm-dd hh:mm")&" ← 与北京时间不符就改 B3"
A6: 时间口径 | B6: 所有截稿、rebuttal、录用通知时间**已统一折算为北京时间（UTC+8）**，不是会议当地时间。本表 148 个会议用 AoE、29 个用 UTC-12，折北京时间需 +20 小时，共 174 个会议的截稿日期因此顺延一天。要对照官网原文时请看「原始时区」列。
A7: 剩余天数 | B7: 「正文截稿 / 状态 / 剩余天数」是公式，打开文件时按电脑当前时间实时计算。Excel 只能读到电脑本地时间，所以先用上方 B3「电脑时区」换算成北京时间再比较——B3 默认 8（北京）；电脑不在北京时区就改成该电脑的 UTC 偏移，如美东填 -4（夏令时）/ -5，B4 会显示换算结果供核对。多轮会议会自动跳到最近一个未过期轮次，摘要截稿、轮次、Rebuttal、录用通知随之切换。「待补清单」里的剩余天数是生成时的快照，仅用于排序。
A8: 方向标签 | B8: 10 个方向对应 CCF 目录的十大领域：人工智能、体系结构/并行/存储、计算机网络、网络与信息安全、软件工程/系统软件、数据库/数据挖掘、计算机科学理论、图形学与多媒体、人机交互与普适计算、交叉/综合/新兴。
A9: 同名会议 | B9: 合并按会议唯一 ID 进行，不按简称。同简称会议中评级高的保留原简称，其余加后缀，如 ACM FSE（软工 A）与 FSE(IACR)（密码学 B）。
A10: 官网核查列 | B10: 【已核实】读到官方 2027 CFP，参会与投稿规则字段来自官方原文。 【2027CFP未发布】官网还没有 2027 的征稿说明——这是当前多数会议的真实状态，不代表信息错误，代表现在查不到。 【官网不可达】会议官网打不开或链接失效。【未找到】官网上没找到对应页面。 【未核查】本轮未覆盖到，字段来自知识补全。
A11: 置信度 | B11: 【高】官网已核实或 ccfddl 官方数据。【中】合理推断，投稿前需复核。【低】沿用上一届口径或推测。 截稿时间另有一层风险：部分 2027 数据是按上届规律外推的（如 SIGMOD 2027 四轮日期与 2026 完全同月同日），官方 CFP 一出就会变。
A12: 轮次取法 | B12: 存在未过期轮次时取最早一个未过期的，否则取最后一轮并标「已截止」。多轮会议（SIGMOD、VLDB 等）的完整轮次已写进「备注」列。
A13: ARR 类 | B13: ACL / NAACL / EACL / COLING 走 ACL Rolling Review 滚动审稿，不直接投稿。主表截稿是该会的 commit / submission 节点，真实投稿看 ARR cycle，见「ARR 轮次」表。ARR 日期存于 arr_cycles.json，全部过期时该表顶部会出现提示。
A14: 作者投稿上限 | B14: 主表拆成「投稿上限(篇)」数字列 + 「上限口径」列（每届 / 每轮 / 每年 / 配额制），可直接用数字筛选。按「同一作者在该届的投稿篇数硬性上限」理解，绝大多数会议不设上限，故填「不限」；填「待确认」表示可能有规定但未核实。官方原文写法见「扩展规则」表。表内没有任何编造的数字。
A15: 新人作者条款 | B15: 「新人作者」指三类人，条款各不相同：首次向该会投稿的作者、学生作者、无资深合作者的独立作者。 「新人作者要求」sheet 把条款拆成 6 类逐项核查：审稿义务/互惠审稿（A）、首投配额（B）、是否强制挂资深作者（C）、投稿账号门槛（D，如 OpenReview 新账号须机构邮箱）、学生与新人通道（E，如 SRW / Doctoral Consortium / Junior PC）、费用与资助（F）。 关键：「无专属条款」是查过且确实没有的结论，不是默认值；CFP 未发布的会一律标「CFP未发布」，不冒充「无」。 「对首投的影响」再分三档：有硬性要求（会卡住或拒稿）、只有利好通道（学生 track / 资助）、仅奖项。 D 类账号门槛只认「投稿时」的要求，录用后走出版流程的 ORCID、版权表单不计入，避免虚高。 最容易卡住首投的几条：ICLR 须指定作者审稿≥3 篇否则 desk reject、无合格互惠审稿人限投 1 篇；OOPSLA / POPL 2027 新政要求每篇至少 1 名资深作者注册 reserve reviewer；AISTATS 无四大 ML 会录用记录者限 3 篇、全体作者不合格则仅 1 篇；MobiSys / SenSys 每篇须 1 位按非学生费率注册；CVPR 无机构邮箱的 OpenReview 新账号需等约两周。
A16: 信息缺口 | B16: 共 112 个会议仍有字段待补，见「待补清单」：官网未写明 61、官网未查到 9、等官方发布 42。「等官方发布」的不要用上届口径填，等 CFP 出来再查；其余两类可按「下一步」列重查，结果写入 recheck/ 目录后重新生成即可合并。
A17: 建议动作 | B17: 1) 先按「未截止」+ 剩余天数 ≤90 筛，再按 CCF 评级与方向锁定 15–20 个目标。 2) 「官网核查」为「已核实」的行可直接用；其余投稿前必须点官网复核。 3) 每年 12 月至次年 3 月是 CFP 集中发布期，本表需定期刷新。

Sheet _轮次
A1: =NOW()+(8-'读我'!$B$3)/24 | B1: dl1 | C1: dl2 | D1: dl3 | E1: dl4 | F1: dl5 | G1: dl6 | H1: dl7 | I1: dl8 | J1: dl9 | K1: dl10 | L1: dl11 | M1: dl12 | N1: abs1 | O1: abs2 | P1: abs3 | Q1: abs4 | R1: abs5 | S1: abs6 | T1: abs7 | U1: abs8 | V1: abs9 | W1: abs10 | X1: abs11 | Y1: abs12 | Z1: reb1 | AA1: reb2 | AB1: reb3 | AC1: reb4 | AD1: reb5 | AE1: reb6 | AF1: reb7 | AG1: reb8 | AH1: reb9 | AI1: reb10 | AJ1: reb11 | AK1: reb12 | AL1: dec1 | AM1: dec2 | AN1: dec3 | AO1: dec4 | AP1: dec5 | AQ1: dec6 | AR1: dec7 | AS1: dec8 | AT1: dec9 | AU1: dec10 | AV1: dec11 | AW1: dec12 | AX1: l1 | AY1: l2 | AZ1: l3 | BA1: l4 | BB1: l5 | BC1: l6 | BD1: l7 | BE1: l8 | BF1: l9 | BG1: l10 | BH1: l11 | BI1: l12
A2: aaai27 | B2: 46232.833 | N2: 46225.833 | Z2: 46321.833 | AL2: 46357.833 | AX2: 单轮
A3: acl27 | B3: 46392.833 | AX3: ARR Submission
A4: cvpr27 | B4: 46343.833 | N4: 46337.833 | Z4: 46420.833 | AL4: 46444.833 | AX4: 单轮
A5: iccv27 | AX5: 单轮
A6: iclr27 | B6: 46291.833 | N6: 46284.833 | Z6: 46345.833 | AL6: 46373.833 | AX6: 单轮
A7: siggraph27 | AX7: 单轮
A8: vr27 | B8: 46266.833 | N8: 46259.833 | AL8: 46395.833 | AX8: 单轮
A9: cav27 | B9: 46408.833 | Z9: 46486.833 | AL9: 46501.833 | AX9: 单轮
A10: lics27 | AX10: 单轮
A11: soda27 | B11: 46213.833 | Z11: 46270.833 | AX11: 单轮
A12: stoc27 | B12: 46329.833 | AL12: 46420.833 | AX12: 单轮
A13: icde27 | B13: 46185.333 | C13: 46338.375 | Z13: 46250.333 | AA13: 46403.375 | AX13: first round | AY13: second round
A14: sigir27 | B14: 46409.833 | N14: 46402.833 | AX14: 单轮
A15: sigkdd27 | B15: 46230.833 | N15: 46223.833 | Z15: 46309.833 | AL15: 46341.833 | AX15: 1st round of 2 total rounds
A16: sigmod27 | B16: 46040.833 | C16: 46130.833 | D16: 46221.833 | E16: 46313.833 | N16: 46033.833 | O16: 46123.833 | P16: 46214.833 | Q16: 46306.833 | Z16: 46099.833 | AA16: 46191.833 | AB16: 46283.833 | AC16: 46374.833 | AL16: 46186.833 | AM16: 46278.833 | AN16: 46369.833 | AO16: 46459.833 | AX16: round 1 | AY16: round 2 | AZ16: round 3 | BA16: round 4
A17: vldb27 | B17: 46114.333 | C17: 46144.333 | D17: 46175.333 | E17: 46205.333 | F17: 46236.333 | G17: 46267.333 | H17: 46297.333 | I17: 46328.375 | J17: 46358.375 | K17: 46389.375 | L17: 46420.375 | M17: 46448.375 | N17: 46107.333 | O17: 46138.333 | P17: 46168.333 | Q17: 46199.333 | R17: 46229.333 | S17: 46260.333 | T17: 46291.333 | U17: 46321.333 | V17: 46352.375 | W17: 46382.375 | X17: 46413.375 | Y17: 46444.375 | AX17: 第1轮 | AY17: 第2轮 | AZ17: 第3轮 | BA17: 第4轮 | BB17: 第5轮 | BC17: 第6轮 | BD17: 第7轮 | BE17: 第8轮 | BF17: 第9轮 | BG17: 第10轮 | BH17: 第11轮 | BI17: 第12轮
A18: asplos27 | B18: 46128.833 | C18: 46275.833 | Z18: 46213.833 | AA18: 46361.833 | AX18: April Cycle Submission Deadline | AY18: September Cycle Submission Deadline
A19: dac27 | B19: 46345.375 | N19: 46338.375 | AL19: 46455.833 | AX19: 单轮
A20: eurosys2027 | B20: 46157.833 | C20: 46290.833 | N20: 46150.833 | O20: 46283.833 | Z20: 46235.833 | AA20: 46396.833 | AX20: Spring Submission Deadline | AY20: Fall Submission Deadline
A21: fast27 | B21: 46099.833 | C21: 46281.833 | Z21: 46163.833 | AA21: 46346.833 | AX21: Spring deadline | AY21: Fall deadline
A22: hpca27 | B22: 46235.833 | N22: 46228.833 | Z22: 46307.833 | AL22: 46333.833 | AX22: 单轮
A23: isca27 | B23: 46343.833 | N23: 46336.833 | Z23: 46455.833 | AL23: 46473.833 | AX23: Main Track; rebuttal/revision period: February 16-March 8, 2027
A24: ppopp27 | B24: 46238.833 | AL24: 46322.833 | AX24: 单轮
A25: chi27 | B25: 46276.833 | Z25: 46360.833 | AL25: 46374.833 | AX25: 单轮
A26: ubicomp27 | AX26: 单轮
A27: www27 | B27: 46321.833 | N27: 46314.833 | AL27: 46392.833 | AX27: 单轮
A28: infocom27 | B28: 46235.833 | N28: 46228.833 | AX28: 单轮
A29: mobicom27 | B29: 46268.833 | N29: 46261.833 | Z29: 46333.833 | AX29: Summer Deadlines
A30: nsdi27 | B30: 46136.499 | C30: 46283.499 | N30: 46129.499 | O30: 46276.499 | AX30: 第1轮 | AY30: 第2轮
A31: sigcomm27 | B31: 46421.833 | AX31: 单轮
A32: ccs27 | AX32: 单轮
A33: eurocrypt27 | B33: 46283.833 | Z33: 46362.833 | AL33: 46406.833 | AX33: 单轮
A34: ndss27 | B34: 46149.833 | C34: 46254.833 | AA34: 46340.833 | AL34: 46282.833 | AM34: 46399.833 | AX34: Summer | AY34: Fall
A35: sp27 | B35: 46185.833 | C35: 46344.833 | N35: 46178.833 | O35: 46337.833 | Z35: 46262.833 | AA35: 46435.833 | AL35: 46277.833 | AM35: 46452.833 | AX35: First Paper submission deadline | AY35: Second Paper submission deadline
A36: uss27 | B36: 46260.833 | C36: 46414.833 | N36: 46253.833 | O36: 46407.833 | Z36: 46339.833 | AA36: 46493.833 | AX36: Cycle 1 Deadline | AY36: Cycle 2 Deadline
A37: fm27 | AX37: 单轮
A38: fse27 | B38: 46298.833 | Z38: 46375.833 | AL38: 46478.833 | AX38: 单轮
A39: icse27 | B39: 46204.833 | N39: 46197.833 | Z39: 46291.833 | AL39: 46375.833 | AX39: Single Submission Cycle Deadline
A40: issta27 | B40: 46399.833 | N40: 46396.833 | Z40: 46472.833 | AL40: 46556.833 | AX40: 单轮
...
